INFO 2020-01-05 16:08:56,648 basehttp 124 "GET / HTTP/1.1" 200 16348
INFO 2020-01-05 16:08:56,758 basehttp 124 "GET /static/admin/css/fonts.css HTTP/1.1" 304 0
INFO 2020-01-05 16:08:56,949 basehttp 124 "GET /static/admin/fonts/Roboto-Bold-webfont.woff HTTP/1.1" 304 0
INFO 2020-01-05 16:08:56,950 basehttp 124 "GET /static/admin/fonts/Roboto-Regular-webfont.woff HTTP/1.1" 304 0
INFO 2020-01-05 16:08:56,956 basehttp 124 "GET /static/admin/fonts/Roboto-Light-webfont.woff HTTP/1.1" 304 0
WARNING 2020-01-05 16:08:57,030 base 93 Not Found: /favicon.ico
WARNING 2020-01-05 16:08:57,031 basehttp 124 "GET /favicon.ico HTTP/1.1" 404 1972
INFO 2020-01-05 16:13:13,032 basehttp 124 "GET /admin HTTP/1.1" 301 0
INFO 2020-01-05 16:13:13,156 basehttp 124 "GET /admin/ HTTP/1.1" 302 0
INFO 2020-01-05 16:13:13,290 basehttp 124 "GET /admin/login/?next=/admin/ HTTP/1.1" 200 1855
INFO 2020-01-05 16:13:13,376 basehttp 124 "GET /static/admin/css/login.css HTTP/1.1" 200 1203
INFO 2020-01-05 16:13:13,412 basehttp 124 "GET /static/admin/css/base.css HTTP/1.1" 200 16106
INFO 2020-01-05 16:13:13,412 basehttp 124 "GET /static/admin/css/responsive.css HTTP/1.1" 200 17894
INFO 2020-01-05 16:14:03,780 basehttp 124 "POST /admin/login/?next=/admin/ HTTP/1.1" 302 0
INFO 2020-01-05 16:14:03,860 basehttp 124 "GET /admin/ HTTP/1.1" 200 6401
INFO 2020-01-05 16:14:03,898 basehttp 124 "GET /static/admin/css/dashboard.css HTTP/1.1" 200 412
INFO 2020-01-05 16:14:03,910 basehttp 124 "GET /static/admin/img/icon-addlink.svg HTTP/1.1" 200 331
INFO 2020-01-05 16:14:03,911 basehttp 124 "GET /static/admin/img/icon-changelink.svg HTTP/1.1" 200 380
INFO 2020-01-05 16:25:57,083 basehttp 124 "GET /admin/auth/group/ HTTP/1.1" 200 3584
INFO 2020-01-05 16:25:57,121 basehttp 124 "GET /static/admin/css/changelists.css HTTP/1.1" 200 6170
INFO 2020-01-05 16:25:57,122 basehttp 124 "GET /static/admin/js/jquery.init.js HTTP/1.1" 200 363
INFO 2020-01-05 16:25:57,130 basehttp 124 "GET /admin/jsi18n/ HTTP/1.1" 200 3185
INFO 2020-01-05 16:25:57,131 basehttp 124 "GET /static/admin/js/core.js HTTP/1.1" 200 7134
INFO 2020-01-05 16:25:57,135 basehttp 124 "GET /static/admin/js/vendor/jquery/jquery.js HTTP/1.1" 200 258648
INFO 2020-01-05 16:25:57,135 basehttp 124 "GET /static/admin/js/admin/RelatedObjectLookups.js HTTP/1.1" 200 6897
INFO 2020-01-05 16:25:57,140 basehttp 124 "GET /static/admin/js/actions.js HTTP/1.1" 200 6502
INFO 2020-01-05 16:25:57,141 basehttp 124 "GET /static/admin/js/urlify.js HTTP/1.1" 200 8729
INFO 2020-01-05 16:25:57,164 basehttp 124 "GET /static/admin/js/prepopulate.js HTTP/1.1" 200 1538
INFO 2020-01-05 16:25:57,166 basehttp 124 "GET /static/admin/js/vendor/xregexp/xregexp.js HTTP/1.1" 200 128820
INFO 2020-01-05 16:25:57,225 basehttp 124 "GET /static/admin/img/search.svg HTTP/1.1" 200 458
INFO 2020-01-05 16:25:57,270 basehttp 124 "GET /static/admin/img/tooltag-add.svg HTTP/1.1" 200 331
INFO 2020-01-05 16:25:59,452 basehttp 124 "GET /admin/ HTTP/1.1" 200 6401
INFO 2020-01-05 16:26:04,537 basehttp 124 "GET /admin/api/food/add/ HTTP/1.1" 200 8538
INFO 2020-01-05 16:26:04,573 basehttp 124 "GET /static/admin/js/change_form.js HTTP/1.1" 200 712
INFO 2020-01-05 16:26:04,576 basehttp 124 "GET /static/admin/img/icon-deletelink.svg HTTP/1.1" 200 392
INFO 2020-01-05 16:26:04,579 basehttp 124 "GET /static/admin/css/forms.css HTTP/1.1" 200 8173
INFO 2020-01-05 16:26:04,583 basehttp 124 "GET /admin/jsi18n/ HTTP/1.1" 200 3185
INFO 2020-01-05 16:26:04,590 basehttp 124 "GET /static/admin/js/prepopulate_init.js HTTP/1.1" 200 495
INFO 2020-01-05 16:26:04,597 basehttp 124 "GET /static/admin/css/widgets.css HTTP/1.1" 200 10340
INFO 2020-01-05 16:26:10,450 basehttp 124 "GET /admin/ HTTP/1.1" 200 6401
INFO 2020-01-05 16:26:13,464 basehttp 124 "GET /admin/api/category/add/ HTTP/1.1" 200 4868
INFO 2020-01-05 16:26:13,499 basehttp 124 "GET /admin/jsi18n/ HTTP/1.1" 200 3185
INFO 2020-01-05 16:26:28,160 basehttp 124 "POST /admin/api/category/add/ HTTP/1.1" 302 0
INFO 2020-01-05 16:26:28,214 basehttp 124 "GET /admin/api/category/add/ HTTP/1.1" 200 5085
INFO 2020-01-05 16:26:28,253 basehttp 124 "GET /admin/jsi18n/ HTTP/1.1" 200 3185
INFO 2020-01-05 16:26:28,286 basehttp 124 "GET /static/admin/img/icon-yes.svg HTTP/1.1" 200 436
INFO 2020-01-05 16:26:34,323 basehttp 124 "POST /admin/api/category/add/ HTTP/1.1" 302 0
INFO 2020-01-05 16:26:34,376 basehttp 124 "GET /admin/api/category/add/ HTTP/1.1" 200 5085
INFO 2020-01-05 16:26:34,426 basehttp 124 "GET /admin/jsi18n/ HTTP/1.1" 200 3185
INFO 2020-01-05 16:26:50,273 basehttp 124 "POST /admin/api/category/add/ HTTP/1.1" 302 0
INFO 2020-01-05 16:26:50,352 basehttp 124 "GET /admin/api/category/ HTTP/1.1" 200 5003
INFO 2020-01-05 16:26:50,402 basehttp 124 "GET /admin/jsi18n/ HTTP/1.1" 200 3185
INFO 2020-01-05 16:26:55,199 basehttp 124 "GET /admin/api/category/add/ HTTP/1.1" 200 4868
INFO 2020-01-05 16:26:55,235 basehttp 124 "GET /admin/jsi18n/ HTTP/1.1" 200 3185
INFO 2020-01-05 16:27:08,575 basehttp 124 "POST /admin/api/category/add/ HTTP/1.1" 302 0
INFO 2020-01-05 16:27:08,646 basehttp 124 "GET /admin/api/category/ HTTP/1.1" 200 5223
INFO 2020-01-05 16:27:08,688 basehttp 124 "GET /admin/jsi18n/ HTTP/1.1" 200 3185
INFO 2020-01-05 16:27:10,952 basehttp 124 "GET /admin/api/category/add/ HTTP/1.1" 200 4868
INFO 2020-01-05 16:27:14,691 basehttp 124 "GET /admin/api/ HTTP/1.1" 200 5178
INFO 2020-01-05 16:27:17,315 basehttp 124 "GET /admin/api/food/add/ HTTP/1.1" 200 8686
INFO 2020-01-05 16:27:17,356 basehttp 124 "GET /admin/jsi18n/ HTTP/1.1" 200 3185
INFO 2020-01-05 16:28:50,241 basehttp 124 "GET /admin/api/fooddetail/add/?_to_field=id&_popup=1 HTTP/1.1" 200 4927
INFO 2020-01-05 16:28:50,300 basehttp 124 "GET /admin/jsi18n/ HTTP/1.1" 200 3185
INFO 2020-01-05 16:30:30,977 basehttp 124 "POST /admin/api/fooddetail/add/?_to_field=id&_popup=1 HTTP/1.1" 200 379
INFO 2020-01-05 16:30:30,998 basehttp 124 "GET /static/admin/js/popup_response.js HTTP/1.1" 200 569
INFO 2020-01-05 16:30:42,684 basehttp 124 "POST /admin/api/fooddetail/add/?_to_field=id&_popup=1 HTTP/1.1" 200 379
INFO 2020-01-05 16:30:47,823 basehttp 124 "POST /admin/api/food/add/ HTTP/1.1" 302 0
INFO 2020-01-05 16:30:47,899 basehttp 124 "GET /admin/api/food/add/ HTTP/1.1" 200 8980
INFO 2020-01-05 16:30:47,934 basehttp 124 "GET /admin/jsi18n/ HTTP/1.1" 200 3185
INFO 2020-01-05 16:31:26,565 basehttp 124 "GET /admin/api/fooddetail/add/?_to_field=id&_popup=1 HTTP/1.1" 200 4927
INFO 2020-01-05 16:31:26,625 basehttp 124 "GET /admin/jsi18n/ HTTP/1.1" 200 3185
INFO 2020-01-05 16:31:48,573 basehttp 124 "POST /admin/api/food/add/ HTTP/1.1" 200 8927
INFO 2020-01-05 16:31:48,653 basehttp 124 "GET /admin/jsi18n/ HTTP/1.1" 200 3185
INFO 2020-01-05 16:31:53,054 basehttp 124 "GET /admin/api/fooddetail/add/?_to_field=id&_popup=1 HTTP/1.1" 200 4927
INFO 2020-01-05 16:31:53,111 basehttp 124 "GET /admin/jsi18n/ HTTP/1.1" 200 3185
INFO 2020-01-05 17:19:40,007 basehttp 124 "POST /admin/api/fooddetail/add/?_to_field=id&_popup=1 HTTP/1.1" 200 379
INFO 2020-01-05 17:20:21,826 basehttp 124 "POST /admin/api/food/add/ HTTP/1.1" 200 8970
INFO 2020-01-05 17:20:21,905 basehttp 124 "GET /admin/jsi18n/ HTTP/1.1" 200 3185
INFO 2020-01-05 17:20:40,304 basehttp 124 "POST /admin/api/food/add/ HTTP/1.1" 302 0
INFO 2020-01-05 17:20:40,576 basehttp 124 "GET /admin/api/food/ HTTP/1.1" 200 4746
INFO 2020-01-05 17:20:40,614 basehttp 124 "GET /admin/jsi18n/ HTTP/1.1" 200 3185
INFO 2020-01-05 17:20:47,339 basehttp 124 "GET /admin/api/food/add/ HTTP/1.1" 200 8815
INFO 2020-01-05 17:20:47,371 basehttp 124 "GET /admin/jsi18n/ HTTP/1.1" 200 3185
INFO 2020-01-05 17:21:22,279 basehttp 124 "GET /admin/api/fooddetail/add/?_to_field=id&_popup=1 HTTP/1.1" 200 4927
INFO 2020-01-05 17:21:22,334 basehttp 124 "GET /admin/jsi18n/ HTTP/1.1" 200 3185
INFO 2020-01-05 17:22:22,242 basehttp 124 "POST /admin/api/fooddetail/add/?_to_field=id&_popup=1 HTTP/1.1" 200 379
INFO 2020-01-05 17:22:28,953 basehttp 124 "POST /admin/api/food/add/ HTTP/1.1" 302 0
INFO 2020-01-05 17:22:29,018 basehttp 124 "GET /admin/api/food/add/ HTTP/1.1" 200 9072
INFO 2020-01-05 17:22:29,062 basehttp 124 "GET /admin/jsi18n/ HTTP/1.1" 200 3185
INFO 2020-01-05 17:22:53,698 basehttp 124 "GET /admin/api/fooddetail/add/?_to_field=id&_popup=1 HTTP/1.1" 200 4927
INFO 2020-01-05 17:22:53,742 basehttp 124 "GET /admin/jsi18n/ HTTP/1.1" 200 3185
INFO 2020-01-05 17:24:01,487 basehttp 124 "POST /admin/api/fooddetail/add/?_to_field=id&_popup=1 HTTP/1.1" 200 379
INFO 2020-01-05 17:24:11,943 basehttp 124 "POST /admin/api/food/add/ HTTP/1.1" 302 0
INFO 2020-01-05 17:24:12,012 basehttp 124 "GET /admin/api/food/ HTTP/1.1" 200 5193
INFO 2020-01-05 17:24:12,048 basehttp 124 "GET /admin/jsi18n/ HTTP/1.1" 200 3185
WARNING 2020-01-05 21:15:26,709 base 93 Not Found: /
WARNING 2020-01-05 21:15:26,728 basehttp 124 "GET / HTTP/1.1" 404 2038
ERROR 2020-01-05 21:15:53,162 exception 118 Internal Server Error: /v1/food/show_food
Traceback (most recent call last):
  File "D:\Virtualenvs\wchat_shop\lib\site-packages\django\core\handlers\exception.py", line 35, in inner
    response = get_response(request)
  File "D:\Virtualenvs\wchat_shop\lib\site-packages\django\core\handlers\base.py", line 128, in _get_response
    response = self.process_exception_by_middleware(e, request)
  File "D:\Virtualenvs\wchat_shop\lib\site-packages\django\core\handlers\base.py", line 126, in _get_response
    response = wrapped_callback(request, *callback_args, **callback_kwargs)
  File "D:\Virtualenvs\wchat_shop\lib\site-packages\django\views\decorators\csrf.py", line 54, in wrapped_view
    return view_func(*args, **kwargs)
  File "D:\Virtualenvs\wchat_shop\lib\site-packages\django\views\generic\base.py", line 69, in view
    return self.dispatch(request, *args, **kwargs)
  File "D:\Virtualenvs\wchat_shop\lib\site-packages\rest_framework\views.py", line 505, in dispatch
    response = self.handle_exception(exc)
  File "D:\Virtualenvs\wchat_shop\lib\site-packages\rest_framework\views.py", line 465, in handle_exception
    self.raise_uncaught_exception(exc)
  File "D:\Virtualenvs\wchat_shop\lib\site-packages\rest_framework\views.py", line 476, in raise_uncaught_exception
    raise exc
  File "D:\Virtualenvs\wchat_shop\lib\site-packages\rest_framework\views.py", line 502, in dispatch
    response = handler(request, *args, **kwargs)
  File "C:\Users\www97\Desktop\2020-01\server\api\views\store_view.py", line 9, in get
    food_obj_list = Food.objects.all(is_show=True, is_delete=True)
TypeError: all() got an unexpected keyword argument 'is_show'
ERROR 2020-01-05 21:15:53,292 basehttp 124 "GET /v1/food/show_food HTTP/1.1" 500 19310
ERROR 2020-01-05 21:21:22,544 exception 118 Internal Server Error: /v1/food/show_food
Traceback (most recent call last):
  File "D:\Virtualenvs\wchat_shop\lib\site-packages\django\core\handlers\exception.py", line 35, in inner
    response = get_response(request)
  File "D:\Virtualenvs\wchat_shop\lib\site-packages\django\core\handlers\base.py", line 128, in _get_response
    response = self.process_exception_by_middleware(e, request)
  File "D:\Virtualenvs\wchat_shop\lib\site-packages\django\core\handlers\base.py", line 126, in _get_response
    response = wrapped_callback(request, *callback_args, **callback_kwargs)
  File "D:\Virtualenvs\wchat_shop\lib\site-packages\django\views\decorators\csrf.py", line 54, in wrapped_view
    return view_func(*args, **kwargs)
  File "D:\Virtualenvs\wchat_shop\lib\site-packages\django\views\generic\base.py", line 69, in view
    return self.dispatch(request, *args, **kwargs)
  File "D:\Virtualenvs\wchat_shop\lib\site-packages\rest_framework\views.py", line 505, in dispatch
    response = self.handle_exception(exc)
  File "D:\Virtualenvs\wchat_shop\lib\site-packages\rest_framework\views.py", line 465, in handle_exception
    self.raise_uncaught_exception(exc)
  File "D:\Virtualenvs\wchat_shop\lib\site-packages\rest_framework\views.py", line 476, in raise_uncaught_exception
    raise exc
  File "D:\Virtualenvs\wchat_shop\lib\site-packages\rest_framework\views.py", line 502, in dispatch
    response = handler(request, *args, **kwargs)
  File "C:\Users\www97\Desktop\2020-01\server\api\views\store_view.py", line 9, in get
    food_obj_list = Food.objects.all(is_show=1, is_delete=1)
TypeError: all() got an unexpected keyword argument 'is_show'
ERROR 2020-01-05 21:21:22,569 basehttp 124 "GET /v1/food/show_food HTTP/1.1" 500 19303
ERROR 2020-01-05 21:21:53,718 exception 118 Internal Server Error: /v1/food/show_food
Traceback (most recent call last):
  File "D:\Virtualenvs\wchat_shop\lib\site-packages\django\core\handlers\exception.py", line 35, in inner
    response = get_response(request)
  File "D:\Virtualenvs\wchat_shop\lib\site-packages\django\core\handlers\base.py", line 128, in _get_response
    response = self.process_exception_by_middleware(e, request)
  File "D:\Virtualenvs\wchat_shop\lib\site-packages\django\core\handlers\base.py", line 126, in _get_response
    response = wrapped_callback(request, *callback_args, **callback_kwargs)
  File "D:\Virtualenvs\wchat_shop\lib\site-packages\django\views\decorators\csrf.py", line 54, in wrapped_view
    return view_func(*args, **kwargs)
  File "D:\Virtualenvs\wchat_shop\lib\site-packages\django\views\generic\base.py", line 69, in view
    return self.dispatch(request, *args, **kwargs)
  File "D:\Virtualenvs\wchat_shop\lib\site-packages\rest_framework\views.py", line 505, in dispatch
    response = self.handle_exception(exc)
  File "D:\Virtualenvs\wchat_shop\lib\site-packages\rest_framework\views.py", line 465, in handle_exception
    self.raise_uncaught_exception(exc)
  File "D:\Virtualenvs\wchat_shop\lib\site-packages\rest_framework\views.py", line 476, in raise_uncaught_exception
    raise exc
  File "D:\Virtualenvs\wchat_shop\lib\site-packages\rest_framework\views.py", line 502, in dispatch
    response = handler(request, *args, **kwargs)
  File "C:\Users\www97\Desktop\2020-01\server\api\views\store_view.py", line 9, in get
    food_obj_list = Food.objects.all(is_show=1)
TypeError: all() got an unexpected keyword argument 'is_show'
ERROR 2020-01-05 21:21:53,743 basehttp 124 "GET /v1/food/show_food HTTP/1.1" 500 19290
ERROR 2020-01-05 21:23:20,112 exception 118 Internal Server Error: /v1/food/show_food
Traceback (most recent call last):
  File "D:\Virtualenvs\wchat_shop\lib\site-packages\rest_framework\fields.py", line 454, in get_attribute
    return get_attribute(instance, self.source_attrs)
  File "D:\Virtualenvs\wchat_shop\lib\site-packages\rest_framework\fields.py", line 94, in get_attribute
    instance = getattr(instance, attr)
AttributeError: 'QuerySet' object has no attribute 'name'

During handling of the above exception, another exception occurred:

Traceback (most recent call last):
  File "D:\Virtualenvs\wchat_shop\lib\site-packages\django\core\handlers\exception.py", line 35, in inner
    response = get_response(request)
  File "D:\Virtualenvs\wchat_shop\lib\site-packages\django\core\handlers\base.py", line 128, in _get_response
    response = self.process_exception_by_middleware(e, request)
  File "D:\Virtualenvs\wchat_shop\lib\site-packages\django\core\handlers\base.py", line 126, in _get_response
    response = wrapped_callback(request, *callback_args, **callback_kwargs)
  File "D:\Virtualenvs\wchat_shop\lib\site-packages\django\views\decorators\csrf.py", line 54, in wrapped_view
    return view_func(*args, **kwargs)
  File "D:\Virtualenvs\wchat_shop\lib\site-packages\django\views\generic\base.py", line 69, in view
    return self.dispatch(request, *args, **kwargs)
  File "D:\Virtualenvs\wchat_shop\lib\site-packages\rest_framework\views.py", line 505, in dispatch
    response = self.handle_exception(exc)
  File "D:\Virtualenvs\wchat_shop\lib\site-packages\rest_framework\views.py", line 465, in handle_exception
    self.raise_uncaught_exception(exc)
  File "D:\Virtualenvs\wchat_shop\lib\site-packages\rest_framework\views.py", line 476, in raise_uncaught_exception
    raise exc
  File "D:\Virtualenvs\wchat_shop\lib\site-packages\rest_framework\views.py", line 502, in dispatch
    response = handler(request, *args, **kwargs)
  File "C:\Users\www97\Desktop\2020-01\server\api\views\store_view.py", line 10, in get
    food_ser_list = FoodsModelSerializer(food_obj_list).data
  File "D:\Virtualenvs\wchat_shop\lib\site-packages\rest_framework\serializers.py", line 562, in data
    ret = super().data
  File "D:\Virtualenvs\wchat_shop\lib\site-packages\rest_framework\serializers.py", line 260, in data
    self._data = self.to_representation(self.instance)
  File "D:\Virtualenvs\wchat_shop\lib\site-packages\rest_framework\serializers.py", line 516, in to_representation
    attribute = field.get_attribute(instance)
  File "D:\Virtualenvs\wchat_shop\lib\site-packages\rest_framework\fields.py", line 487, in get_attribute
    raise type(exc)(msg)
AttributeError: Got AttributeError when attempting to get a value for field `name` on serializer `FoodsModelSerializer`.
The serializer field might be named incorrectly and not match any attribute or key on the `QuerySet` instance.
Original exception text was: 'QuerySet' object has no attribute 'name'.
ERROR 2020-01-05 21:23:20,404 basehttp 124 "GET /v1/food/show_food HTTP/1.1" 500 20805
ERROR 2020-01-05 21:23:32,356 exception 118 Internal Server Error: /v1/food/show_food
Traceback (most recent call last):
  File "D:\Virtualenvs\wchat_shop\lib\site-packages\rest_framework\fields.py", line 454, in get_attribute
    return get_attribute(instance, self.source_attrs)
  File "D:\Virtualenvs\wchat_shop\lib\site-packages\rest_framework\fields.py", line 94, in get_attribute
    instance = getattr(instance, attr)
AttributeError: 'QuerySet' object has no attribute 'name'

During handling of the above exception, another exception occurred:

Traceback (most recent call last):
  File "D:\Virtualenvs\wchat_shop\lib\site-packages\django\core\handlers\exception.py", line 35, in inner
    response = get_response(request)
  File "D:\Virtualenvs\wchat_shop\lib\site-packages\django\core\handlers\base.py", line 128, in _get_response
    response = self.process_exception_by_middleware(e, request)
  File "D:\Virtualenvs\wchat_shop\lib\site-packages\django\core\handlers\base.py", line 126, in _get_response
    response = wrapped_callback(request, *callback_args, **callback_kwargs)
  File "D:\Virtualenvs\wchat_shop\lib\site-packages\django\views\decorators\csrf.py", line 54, in wrapped_view
    return view_func(*args, **kwargs)
  File "D:\Virtualenvs\wchat_shop\lib\site-packages\django\views\generic\base.py", line 69, in view
    return self.dispatch(request, *args, **kwargs)
  File "D:\Virtualenvs\wchat_shop\lib\site-packages\rest_framework\views.py", line 505, in dispatch
    response = self.handle_exception(exc)
  File "D:\Virtualenvs\wchat_shop\lib\site-packages\rest_framework\views.py", line 465, in handle_exception
    self.raise_uncaught_exception(exc)
  File "D:\Virtualenvs\wchat_shop\lib\site-packages\rest_framework\views.py", line 476, in raise_uncaught_exception
    raise exc
  File "D:\Virtualenvs\wchat_shop\lib\site-packages\rest_framework\views.py", line 502, in dispatch
    response = handler(request, *args, **kwargs)
  File "C:\Users\www97\Desktop\2020-01\server\api\views\store_view.py", line 10, in get
    food_ser_list = FoodsModelSerializer(food_obj_list).data
  File "D:\Virtualenvs\wchat_shop\lib\site-packages\rest_framework\serializers.py", line 562, in data
    ret = super().data
  File "D:\Virtualenvs\wchat_shop\lib\site-packages\rest_framework\serializers.py", line 260, in data
    self._data = self.to_representation(self.instance)
  File "D:\Virtualenvs\wchat_shop\lib\site-packages\rest_framework\serializers.py", line 516, in to_representation
    attribute = field.get_attribute(instance)
  File "D:\Virtualenvs\wchat_shop\lib\site-packages\rest_framework\fields.py", line 487, in get_attribute
    raise type(exc)(msg)
AttributeError: Got AttributeError when attempting to get a value for field `name` on serializer `FoodsModelSerializer`.
The serializer field might be named incorrectly and not match any attribute or key on the `QuerySet` instance.
Original exception text was: 'QuerySet' object has no attribute 'name'.
ERROR 2020-01-05 21:23:32,421 basehttp 124 "GET /v1/food/show_food HTTP/1.1" 500 20805
ERROR 2020-01-05 21:26:11,740 exception 118 Internal Server Error: /v1/food/show_food
Traceback (most recent call last):
  File "D:\Virtualenvs\wchat_shop\lib\site-packages\rest_framework\fields.py", line 454, in get_attribute
    return get_attribute(instance, self.source_attrs)
  File "D:\Virtualenvs\wchat_shop\lib\site-packages\rest_framework\fields.py", line 94, in get_attribute
    instance = getattr(instance, attr)
AttributeError: 'QuerySet' object has no attribute 'name'

During handling of the above exception, another exception occurred:

Traceback (most recent call last):
  File "D:\Virtualenvs\wchat_shop\lib\site-packages\django\core\handlers\exception.py", line 35, in inner
    response = get_response(request)
  File "D:\Virtualenvs\wchat_shop\lib\site-packages\django\core\handlers\base.py", line 128, in _get_response
    response = self.process_exception_by_middleware(e, request)
  File "D:\Virtualenvs\wchat_shop\lib\site-packages\django\core\handlers\base.py", line 126, in _get_response
    response = wrapped_callback(request, *callback_args, **callback_kwargs)
  File "D:\Virtualenvs\wchat_shop\lib\site-packages\django\views\decorators\csrf.py", line 54, in wrapped_view
    return view_func(*args, **kwargs)
  File "D:\Virtualenvs\wchat_shop\lib\site-packages\django\views\generic\base.py", line 69, in view
    return self.dispatch(request, *args, **kwargs)
  File "D:\Virtualenvs\wchat_shop\lib\site-packages\rest_framework\views.py", line 505, in dispatch
    response = self.handle_exception(exc)
  File "D:\Virtualenvs\wchat_shop\lib\site-packages\rest_framework\views.py", line 465, in handle_exception
    self.raise_uncaught_exception(exc)
  File "D:\Virtualenvs\wchat_shop\lib\site-packages\rest_framework\views.py", line 476, in raise_uncaught_exception
    raise exc
  File "D:\Virtualenvs\wchat_shop\lib\site-packages\rest_framework\views.py", line 502, in dispatch
    response = handler(request, *args, **kwargs)
  File "C:\Users\www97\Desktop\2020-01\server\api\views\store_view.py", line 11, in get
    food_ser_list = FoodsModelSerializer(food_obj_list).data
  File "D:\Virtualenvs\wchat_shop\lib\site-packages\rest_framework\serializers.py", line 562, in data
    ret = super().data
  File "D:\Virtualenvs\wchat_shop\lib\site-packages\rest_framework\serializers.py", line 260, in data
    self._data = self.to_representation(self.instance)
  File "D:\Virtualenvs\wchat_shop\lib\site-packages\rest_framework\serializers.py", line 516, in to_representation
    attribute = field.get_attribute(instance)
  File "D:\Virtualenvs\wchat_shop\lib\site-packages\rest_framework\fields.py", line 487, in get_attribute
    raise type(exc)(msg)
AttributeError: Got AttributeError when attempting to get a value for field `name` on serializer `FoodsModelSerializer`.
The serializer field might be named incorrectly and not match any attribute or key on the `QuerySet` instance.
Original exception text was: 'QuerySet' object has no attribute 'name'.
ERROR 2020-01-05 21:26:11,782 basehttp 124 "GET /v1/food/show_food HTTP/1.1" 500 20805
INFO 2020-01-05 21:26:50,082 basehttp 124 "GET /v1/food/show_food HTTP/1.1" 200 4
ERROR 2020-01-05 21:27:34,537 exception 118 Internal Server Error: /v1/food/show_food
Traceback (most recent call last):
  File "D:\Virtualenvs\wchat_shop\lib\site-packages\django\core\handlers\exception.py", line 35, in inner
    response = get_response(request)
  File "D:\Virtualenvs\wchat_shop\lib\site-packages\django\core\handlers\base.py", line 128, in _get_response
    response = self.process_exception_by_middleware(e, request)
  File "D:\Virtualenvs\wchat_shop\lib\site-packages\django\core\handlers\base.py", line 126, in _get_response
    response = wrapped_callback(request, *callback_args, **callback_kwargs)
  File "D:\Virtualenvs\wchat_shop\lib\site-packages\django\views\decorators\csrf.py", line 54, in wrapped_view
    return view_func(*args, **kwargs)
  File "D:\Virtualenvs\wchat_shop\lib\site-packages\django\views\generic\base.py", line 69, in view
    return self.dispatch(request, *args, **kwargs)
  File "D:\Virtualenvs\wchat_shop\lib\site-packages\rest_framework\views.py", line 505, in dispatch
    response = self.handle_exception(exc)
  File "D:\Virtualenvs\wchat_shop\lib\site-packages\rest_framework\views.py", line 465, in handle_exception
    self.raise_uncaught_exception(exc)
  File "D:\Virtualenvs\wchat_shop\lib\site-packages\rest_framework\views.py", line 476, in raise_uncaught_exception
    raise exc
  File "D:\Virtualenvs\wchat_shop\lib\site-packages\rest_framework\views.py", line 502, in dispatch
    response = handler(request, *args, **kwargs)
  File "C:\Users\www97\Desktop\2020-01\server\api\views\store_view.py", line 12, in get
    print(food_ser_list.data)
AttributeError: 'ReturnList' object has no attribute 'data'
ERROR 2020-01-05 21:27:34,560 basehttp 124 "GET /v1/food/show_food HTTP/1.1" 500 19269
ERROR 2020-01-05 21:27:55,629 exception 118 Internal Server Error: /v1/food/show_food
Traceback (most recent call last):
  File "D:\Virtualenvs\wchat_shop\lib\site-packages\django\core\handlers\exception.py", line 35, in inner
    response = get_response(request)
  File "D:\Virtualenvs\wchat_shop\lib\site-packages\django\core\handlers\base.py", line 128, in _get_response
    response = self.process_exception_by_middleware(e, request)
  File "D:\Virtualenvs\wchat_shop\lib\site-packages\django\core\handlers\base.py", line 126, in _get_response
    response = wrapped_callback(request, *callback_args, **callback_kwargs)
  File "D:\Virtualenvs\wchat_shop\lib\site-packages\django\views\decorators\csrf.py", line 54, in wrapped_view
    return view_func(*args, **kwargs)
  File "D:\Virtualenvs\wchat_shop\lib\site-packages\django\views\generic\base.py", line 69, in view
    return self.dispatch(request, *args, **kwargs)
  File "D:\Virtualenvs\wchat_shop\lib\site-packages\rest_framework\views.py", line 505, in dispatch
    response = self.handle_exception(exc)
  File "D:\Virtualenvs\wchat_shop\lib\site-packages\rest_framework\views.py", line 465, in handle_exception
    self.raise_uncaught_exception(exc)
  File "D:\Virtualenvs\wchat_shop\lib\site-packages\rest_framework\views.py", line 476, in raise_uncaught_exception
    raise exc
  File "D:\Virtualenvs\wchat_shop\lib\site-packages\rest_framework\views.py", line 502, in dispatch
    response = handler(request, *args, **kwargs)
  File "C:\Users\www97\Desktop\2020-01\server\api\views\store_view.py", line 12, in get
    print(food_ser_list)
AttributeError: 'ReturnList' object has no attribute 'data'
ERROR 2020-01-05 21:27:55,645 basehttp 124 "GET /v1/food/show_food HTTP/1.1" 500 19265
INFO 2020-01-05 21:28:02,518 basehttp 124 "GET /v1/food/show_food HTTP/1.1" 200 4
ERROR 2020-01-05 21:28:26,026 exception 118 Internal Server Error: /v1/food/show_food
Traceback (most recent call last):
  File "D:\Virtualenvs\wchat_shop\lib\site-packages\django\core\handlers\exception.py", line 35, in inner
    response = get_response(request)
  File "D:\Virtualenvs\wchat_shop\lib\site-packages\django\core\handlers\base.py", line 158, in _get_response
    response = self.process_exception_by_middleware(e, request)
  File "D:\Virtualenvs\wchat_shop\lib\site-packages\django\core\handlers\base.py", line 156, in _get_response
    response = response.render()
  File "D:\Virtualenvs\wchat_shop\lib\site-packages\django\template\response.py", line 106, in render
    self.content = self.rendered_content
  File "D:\Virtualenvs\wchat_shop\lib\site-packages\rest_framework\response.py", line 70, in rendered_content
    ret = renderer.render(self.data, accepted_media_type, context)
  File "D:\Virtualenvs\wchat_shop\lib\site-packages\rest_framework\renderers.py", line 103, in render
    allow_nan=not self.strict, separators=separators
  File "D:\Virtualenvs\wchat_shop\lib\site-packages\rest_framework\utils\json.py", line 25, in dumps
    return json.dumps(*args, **kwargs)
  File "D:\python3.6\Lib\json\__init__.py", line 238, in dumps
    **kw).encode(obj)
  File "D:\python3.6\Lib\json\encoder.py", line 199, in encode
    chunks = self.iterencode(o, _one_shot=True)
  File "D:\python3.6\Lib\json\encoder.py", line 257, in iterencode
    return _iterencode(o, 0)
  File "D:\Virtualenvs\wchat_shop\lib\site-packages\rest_framework\utils\encoders.py", line 67, in default
    return super().default(obj)
  File "D:\python3.6\Lib\json\encoder.py", line 180, in default
    o.__class__.__name__)
TypeError: Object of type 'Food' is not JSON serializable
ERROR 2020-01-05 21:28:26,466 basehttp 124 "GET /v1/food/show_food HTTP/1.1" 500 105912
ERROR 2020-01-05 21:31:02,561 exception 118 Internal Server Error: /v1/food/show_food
Traceback (most recent call last):
  File "D:\Virtualenvs\wchat_shop\lib\site-packages\django\core\handlers\exception.py", line 35, in inner
    response = get_response(request)
  File "D:\Virtualenvs\wchat_shop\lib\site-packages\django\core\handlers\base.py", line 128, in _get_response
    response = self.process_exception_by_middleware(e, request)
  File "D:\Virtualenvs\wchat_shop\lib\site-packages\django\core\handlers\base.py", line 126, in _get_response
    response = wrapped_callback(request, *callback_args, **callback_kwargs)
  File "D:\Virtualenvs\wchat_shop\lib\site-packages\django\views\decorators\csrf.py", line 54, in wrapped_view
    return view_func(*args, **kwargs)
  File "D:\Virtualenvs\wchat_shop\lib\site-packages\django\views\generic\base.py", line 69, in view
    return self.dispatch(request, *args, **kwargs)
  File "D:\Virtualenvs\wchat_shop\lib\site-packages\rest_framework\views.py", line 505, in dispatch
    response = self.handle_exception(exc)
  File "D:\Virtualenvs\wchat_shop\lib\site-packages\rest_framework\views.py", line 465, in handle_exception
    self.raise_uncaught_exception(exc)
  File "D:\Virtualenvs\wchat_shop\lib\site-packages\rest_framework\views.py", line 476, in raise_uncaught_exception
    raise exc
  File "D:\Virtualenvs\wchat_shop\lib\site-packages\rest_framework\views.py", line 502, in dispatch
    response = handler(request, *args, **kwargs)
  File "C:\Users\www97\Desktop\2020-01\server\api\views\store_view.py", line 13, in get
    print(food_ser_list.id)
AttributeError: 'ReturnList' object has no attribute 'id'
ERROR 2020-01-05 21:31:02,589 basehttp 124 "GET /v1/food/show_food HTTP/1.1" 500 19263
ERROR 2020-01-05 21:31:05,933 exception 118 Internal Server Error: /v1/food/show_food
Traceback (most recent call last):
  File "D:\Virtualenvs\wchat_shop\lib\site-packages\django\core\handlers\exception.py", line 35, in inner
    response = get_response(request)
  File "D:\Virtualenvs\wchat_shop\lib\site-packages\django\core\handlers\base.py", line 128, in _get_response
    response = self.process_exception_by_middleware(e, request)
  File "D:\Virtualenvs\wchat_shop\lib\site-packages\django\core\handlers\base.py", line 126, in _get_response
    response = wrapped_callback(request, *callback_args, **callback_kwargs)
  File "D:\Virtualenvs\wchat_shop\lib\site-packages\django\views\decorators\csrf.py", line 54, in wrapped_view
    return view_func(*args, **kwargs)
  File "D:\Virtualenvs\wchat_shop\lib\site-packages\django\views\generic\base.py", line 69, in view
    return self.dispatch(request, *args, **kwargs)
  File "D:\Virtualenvs\wchat_shop\lib\site-packages\rest_framework\views.py", line 505, in dispatch
    response = self.handle_exception(exc)
  File "D:\Virtualenvs\wchat_shop\lib\site-packages\rest_framework\views.py", line 465, in handle_exception
    self.raise_uncaught_exception(exc)
  File "D:\Virtualenvs\wchat_shop\lib\site-packages\rest_framework\views.py", line 476, in raise_uncaught_exception
    raise exc
  File "D:\Virtualenvs\wchat_shop\lib\site-packages\rest_framework\views.py", line 502, in dispatch
    response = handler(request, *args, **kwargs)
  File "C:\Users\www97\Desktop\2020-01\server\api\views\store_view.py", line 13, in get
    print(food_ser_list.id)
AttributeError: 'ReturnList' object has no attribute 'id'
ERROR 2020-01-05 21:31:05,948 basehttp 124 "GET /v1/food/show_food HTTP/1.1" 500 19264
ERROR 2020-01-05 21:31:50,824 exception 118 Internal Server Error: /v1/food/show_food
Traceback (most recent call last):
  File "D:\Virtualenvs\wchat_shop\lib\site-packages\django\core\handlers\exception.py", line 35, in inner
    response = get_response(request)
  File "D:\Virtualenvs\wchat_shop\lib\site-packages\django\core\handlers\base.py", line 128, in _get_response
    response = self.process_exception_by_middleware(e, request)
  File "D:\Virtualenvs\wchat_shop\lib\site-packages\django\core\handlers\base.py", line 126, in _get_response
    response = wrapped_callback(request, *callback_args, **callback_kwargs)
  File "D:\Virtualenvs\wchat_shop\lib\site-packages\django\views\decorators\csrf.py", line 54, in wrapped_view
    return view_func(*args, **kwargs)
  File "D:\Virtualenvs\wchat_shop\lib\site-packages\django\views\generic\base.py", line 69, in view
    return self.dispatch(request, *args, **kwargs)
  File "D:\Virtualenvs\wchat_shop\lib\site-packages\rest_framework\views.py", line 505, in dispatch
    response = self.handle_exception(exc)
  File "D:\Virtualenvs\wchat_shop\lib\site-packages\rest_framework\views.py", line 465, in handle_exception
    self.raise_uncaught_exception(exc)
  File "D:\Virtualenvs\wchat_shop\lib\site-packages\rest_framework\views.py", line 476, in raise_uncaught_exception
    raise exc
  File "D:\Virtualenvs\wchat_shop\lib\site-packages\rest_framework\views.py", line 502, in dispatch
    response = handler(request, *args, **kwargs)
  File "C:\Users\www97\Desktop\2020-01\server\api\views\store_view.py", line 13, in get
    print(food_ser_list.id)
AttributeError: 'ReturnList' object has no attribute 'id'
ERROR 2020-01-05 21:31:50,849 basehttp 124 "GET /v1/food/show_food HTTP/1.1" 500 19263
ERROR 2020-01-05 21:32:04,709 exception 118 Internal Server Error: /v1/food/show_food
Traceback (most recent call last):
  File "D:\Virtualenvs\wchat_shop\lib\site-packages\django\core\handlers\exception.py", line 35, in inner
    response = get_response(request)
  File "D:\Virtualenvs\wchat_shop\lib\site-packages\django\core\handlers\base.py", line 128, in _get_response
    response = self.process_exception_by_middleware(e, request)
  File "D:\Virtualenvs\wchat_shop\lib\site-packages\django\core\handlers\base.py", line 126, in _get_response
    response = wrapped_callback(request, *callback_args, **callback_kwargs)
  File "D:\Virtualenvs\wchat_shop\lib\site-packages\django\views\decorators\csrf.py", line 54, in wrapped_view
    return view_func(*args, **kwargs)
  File "D:\Virtualenvs\wchat_shop\lib\site-packages\django\views\generic\base.py", line 69, in view
    return self.dispatch(request, *args, **kwargs)
  File "D:\Virtualenvs\wchat_shop\lib\site-packages\rest_framework\views.py", line 505, in dispatch
    response = self.handle_exception(exc)
  File "D:\Virtualenvs\wchat_shop\lib\site-packages\rest_framework\views.py", line 465, in handle_exception
    self.raise_uncaught_exception(exc)
  File "D:\Virtualenvs\wchat_shop\lib\site-packages\rest_framework\views.py", line 476, in raise_uncaught_exception
    raise exc
  File "D:\Virtualenvs\wchat_shop\lib\site-packages\rest_framework\views.py", line 502, in dispatch
    response = handler(request, *args, **kwargs)
  File "C:\Users\www97\Desktop\2020-01\server\api\views\store_view.py", line 13, in get
    print(food_ser_list.id)
AttributeError: 'ReturnList' object has no attribute 'id'
ERROR 2020-01-05 21:32:04,738 basehttp 124 "GET /v1/food/show_food HTTP/1.1" 500 19263
INFO 2020-01-05 21:32:54,287 basehttp 124 "GET /v1/food/show_food HTTP/1.1" 200 4
INFO 2020-01-05 21:36:26,820 basehttp 124 "GET /v1/food/show_food HTTP/1.1" 200 4
ERROR 2020-01-05 21:39:17,774 exception 118 Internal Server Error: /v1/food/show_food
Traceback (most recent call last):
  File "D:\Virtualenvs\wchat_shop\lib\site-packages\django\core\handlers\exception.py", line 35, in inner
    response = get_response(request)
  File "D:\Virtualenvs\wchat_shop\lib\site-packages\django\core\handlers\base.py", line 128, in _get_response
    response = self.process_exception_by_middleware(e, request)
  File "D:\Virtualenvs\wchat_shop\lib\site-packages\django\core\handlers\base.py", line 126, in _get_response
    response = wrapped_callback(request, *callback_args, **callback_kwargs)
  File "D:\Virtualenvs\wchat_shop\lib\site-packages\django\views\decorators\csrf.py", line 54, in wrapped_view
    return view_func(*args, **kwargs)
  File "D:\Virtualenvs\wchat_shop\lib\site-packages\django\views\generic\base.py", line 69, in view
    return self.dispatch(request, *args, **kwargs)
  File "D:\Virtualenvs\wchat_shop\lib\site-packages\rest_framework\views.py", line 505, in dispatch
    response = self.handle_exception(exc)
  File "D:\Virtualenvs\wchat_shop\lib\site-packages\rest_framework\views.py", line 465, in handle_exception
    self.raise_uncaught_exception(exc)
  File "D:\Virtualenvs\wchat_shop\lib\site-packages\rest_framework\views.py", line 476, in raise_uncaught_exception
    raise exc
  File "D:\Virtualenvs\wchat_shop\lib\site-packages\rest_framework\views.py", line 502, in dispatch
    response = handler(request, *args, **kwargs)
  File "C:\Users\www97\Desktop\2020-01\server\api\views\store_view.py", line 22, in get
    send_data = JsonResponse(send_list)
  File "D:\Virtualenvs\wchat_shop\lib\site-packages\django\http\response.py", line 503, in __init__
    'In order to allow non-dict objects to be serialized set the '
TypeError: In order to allow non-dict objects to be serialized set the safe parameter to False.
ERROR 2020-01-05 21:39:17,816 basehttp 124 "GET /v1/food/show_food HTTP/1.1" 500 19525
ERROR 2020-01-05 21:41:28,940 exception 118 Internal Server Error: /v1/food/show_food
Traceback (most recent call last):
  File "D:\Virtualenvs\wchat_shop\lib\site-packages\django\core\handlers\exception.py", line 35, in inner
    response = get_response(request)
  File "D:\Virtualenvs\wchat_shop\lib\site-packages\django\core\handlers\base.py", line 128, in _get_response
    response = self.process_exception_by_middleware(e, request)
  File "D:\Virtualenvs\wchat_shop\lib\site-packages\django\core\handlers\base.py", line 126, in _get_response
    response = wrapped_callback(request, *callback_args, **callback_kwargs)
  File "D:\Virtualenvs\wchat_shop\lib\site-packages\django\views\decorators\csrf.py", line 54, in wrapped_view
    return view_func(*args, **kwargs)
  File "D:\Virtualenvs\wchat_shop\lib\site-packages\django\views\generic\base.py", line 69, in view
    return self.dispatch(request, *args, **kwargs)
  File "D:\Virtualenvs\wchat_shop\lib\site-packages\rest_framework\views.py", line 505, in dispatch
    response = self.handle_exception(exc)
  File "D:\Virtualenvs\wchat_shop\lib\site-packages\rest_framework\views.py", line 465, in handle_exception
    self.raise_uncaught_exception(exc)
  File "D:\Virtualenvs\wchat_shop\lib\site-packages\rest_framework\views.py", line 476, in raise_uncaught_exception
    raise exc
  File "D:\Virtualenvs\wchat_shop\lib\site-packages\rest_framework\views.py", line 502, in dispatch
    response = handler(request, *args, **kwargs)
  File "C:\Users\www97\Desktop\2020-01\server\api\views\store_view.py", line 22, in get
    send_data = JsonResponse(send_list)
  File "D:\Virtualenvs\wchat_shop\lib\site-packages\django\http\response.py", line 503, in __init__
    'In order to allow non-dict objects to be serialized set the '
TypeError: In order to allow non-dict objects to be serialized set the safe parameter to False.
ERROR 2020-01-05 21:41:28,963 basehttp 124 "GET /v1/food/show_food HTTP/1.1" 500 19525
ERROR 2020-01-05 21:41:31,664 exception 118 Internal Server Error: /v1/food/show_food
Traceback (most recent call last):
  File "D:\Virtualenvs\wchat_shop\lib\site-packages\django\core\handlers\exception.py", line 35, in inner
    response = get_response(request)
  File "D:\Virtualenvs\wchat_shop\lib\site-packages\django\core\handlers\base.py", line 128, in _get_response
    response = self.process_exception_by_middleware(e, request)
  File "D:\Virtualenvs\wchat_shop\lib\site-packages\django\core\handlers\base.py", line 126, in _get_response
    response = wrapped_callback(request, *callback_args, **callback_kwargs)
  File "D:\Virtualenvs\wchat_shop\lib\site-packages\django\views\decorators\csrf.py", line 54, in wrapped_view
    return view_func(*args, **kwargs)
  File "D:\Virtualenvs\wchat_shop\lib\site-packages\django\views\generic\base.py", line 69, in view
    return self.dispatch(request, *args, **kwargs)
  File "D:\Virtualenvs\wchat_shop\lib\site-packages\rest_framework\views.py", line 505, in dispatch
    response = self.handle_exception(exc)
  File "D:\Virtualenvs\wchat_shop\lib\site-packages\rest_framework\views.py", line 465, in handle_exception
    self.raise_uncaught_exception(exc)
  File "D:\Virtualenvs\wchat_shop\lib\site-packages\rest_framework\views.py", line 476, in raise_uncaught_exception
    raise exc
  File "D:\Virtualenvs\wchat_shop\lib\site-packages\rest_framework\views.py", line 502, in dispatch
    response = handler(request, *args, **kwargs)
  File "C:\Users\www97\Desktop\2020-01\server\api\views\store_view.py", line 22, in get
    send_data = JsonResponse(send_list)
  File "D:\Virtualenvs\wchat_shop\lib\site-packages\django\http\response.py", line 503, in __init__
    'In order to allow non-dict objects to be serialized set the '
TypeError: In order to allow non-dict objects to be serialized set the safe parameter to False.
ERROR 2020-01-05 21:41:31,681 basehttp 124 "GET /v1/food/show_food HTTP/1.1" 500 19526
ERROR 2020-01-05 21:42:09,412 exception 118 Internal Server Error: /v1/food/show_food
Traceback (most recent call last):
  File "D:\Virtualenvs\wchat_shop\lib\site-packages\django\core\handlers\exception.py", line 35, in inner
    response = get_response(request)
  File "D:\Virtualenvs\wchat_shop\lib\site-packages\django\core\handlers\base.py", line 128, in _get_response
    response = self.process_exception_by_middleware(e, request)
  File "D:\Virtualenvs\wchat_shop\lib\site-packages\django\core\handlers\base.py", line 126, in _get_response
    response = wrapped_callback(request, *callback_args, **callback_kwargs)
  File "D:\Virtualenvs\wchat_shop\lib\site-packages\django\views\decorators\csrf.py", line 54, in wrapped_view
    return view_func(*args, **kwargs)
  File "D:\Virtualenvs\wchat_shop\lib\site-packages\django\views\generic\base.py", line 69, in view
    return self.dispatch(request, *args, **kwargs)
  File "D:\Virtualenvs\wchat_shop\lib\site-packages\rest_framework\views.py", line 505, in dispatch
    response = self.handle_exception(exc)
  File "D:\Virtualenvs\wchat_shop\lib\site-packages\rest_framework\views.py", line 465, in handle_exception
    self.raise_uncaught_exception(exc)
  File "D:\Virtualenvs\wchat_shop\lib\site-packages\rest_framework\views.py", line 476, in raise_uncaught_exception
    raise exc
  File "D:\Virtualenvs\wchat_shop\lib\site-packages\rest_framework\views.py", line 502, in dispatch
    response = handler(request, *args, **kwargs)
  File "C:\Users\www97\Desktop\2020-01\server\api\views\store_view.py", line 22, in get
    send_data = JsonResponse(send_list)
  File "D:\Virtualenvs\wchat_shop\lib\site-packages\django\http\response.py", line 509, in __init__
    data = json.dumps(data, cls=encoder, **json_dumps_params)
  File "D:\python3.6\Lib\json\__init__.py", line 238, in dumps
    **kw).encode(obj)
  File "D:\python3.6\Lib\json\encoder.py", line 199, in encode
    chunks = self.iterencode(o, _one_shot=True)
  File "D:\python3.6\Lib\json\encoder.py", line 257, in iterencode
    return _iterencode(o, 0)
  File "D:\Virtualenvs\wchat_shop\lib\site-packages\django\core\serializers\json.py", line 104, in default
    return super().default(o)
  File "D:\python3.6\Lib\json\encoder.py", line 180, in default
    o.__class__.__name__)
TypeError: Object of type 'ImageFieldFile' is not JSON serializable
ERROR 2020-01-05 21:42:09,460 basehttp 124 "GET /v1/food/show_food HTTP/1.1" 500 19990
ERROR 2020-01-05 21:47:08,361 exception 118 Internal Server Error: /v1/food/show_food
Traceback (most recent call last):
  File "D:\Virtualenvs\wchat_shop\lib\site-packages\django\core\handlers\exception.py", line 35, in inner
    response = get_response(request)
  File "D:\Virtualenvs\wchat_shop\lib\site-packages\django\core\handlers\base.py", line 158, in _get_response
    response = self.process_exception_by_middleware(e, request)
  File "D:\Virtualenvs\wchat_shop\lib\site-packages\django\core\handlers\base.py", line 156, in _get_response
    response = response.render()
  File "D:\Virtualenvs\wchat_shop\lib\site-packages\django\template\response.py", line 106, in render
    self.content = self.rendered_content
  File "D:\Virtualenvs\wchat_shop\lib\site-packages\rest_framework\response.py", line 70, in rendered_content
    ret = renderer.render(self.data, accepted_media_type, context)
  File "D:\Virtualenvs\wchat_shop\lib\site-packages\rest_framework\renderers.py", line 103, in render
    allow_nan=not self.strict, separators=separators
  File "D:\Virtualenvs\wchat_shop\lib\site-packages\rest_framework\utils\json.py", line 25, in dumps
    return json.dumps(*args, **kwargs)
  File "D:\python3.6\Lib\json\__init__.py", line 238, in dumps
    **kw).encode(obj)
  File "D:\python3.6\Lib\json\encoder.py", line 199, in encode
    chunks = self.iterencode(o, _one_shot=True)
  File "D:\python3.6\Lib\json\encoder.py", line 257, in iterencode
    return _iterencode(o, 0)
  File "D:\Virtualenvs\wchat_shop\lib\site-packages\rest_framework\utils\encoders.py", line 50, in default
    return obj.decode()
UnicodeDecodeError: 'utf-8' codec can't decode byte 0xff in position 0: invalid start byte
ERROR 2020-01-05 21:47:08,522 basehttp 124 "GET /v1/food/show_food HTTP/1.1" 500 111391
ERROR 2020-01-05 21:47:51,822 exception 118 Internal Server Error: /v1/food/show_food
Traceback (most recent call last):
  File "D:\Virtualenvs\wchat_shop\lib\site-packages\django\core\handlers\exception.py", line 35, in inner
    response = get_response(request)
  File "D:\Virtualenvs\wchat_shop\lib\site-packages\django\core\handlers\base.py", line 158, in _get_response
    response = self.process_exception_by_middleware(e, request)
  File "D:\Virtualenvs\wchat_shop\lib\site-packages\django\core\handlers\base.py", line 156, in _get_response
    response = response.render()
  File "D:\Virtualenvs\wchat_shop\lib\site-packages\django\template\response.py", line 106, in render
    self.content = self.rendered_content
  File "D:\Virtualenvs\wchat_shop\lib\site-packages\rest_framework\response.py", line 70, in rendered_content
    ret = renderer.render(self.data, accepted_media_type, context)
  File "D:\Virtualenvs\wchat_shop\lib\site-packages\rest_framework\renderers.py", line 103, in render
    allow_nan=not self.strict, separators=separators
  File "D:\Virtualenvs\wchat_shop\lib\site-packages\rest_framework\utils\json.py", line 25, in dumps
    return json.dumps(*args, **kwargs)
  File "D:\python3.6\Lib\json\__init__.py", line 238, in dumps
    **kw).encode(obj)
  File "D:\python3.6\Lib\json\encoder.py", line 199, in encode
    chunks = self.iterencode(o, _one_shot=True)
  File "D:\python3.6\Lib\json\encoder.py", line 257, in iterencode
    return _iterencode(o, 0)
  File "D:\Virtualenvs\wchat_shop\lib\site-packages\rest_framework\utils\encoders.py", line 50, in default
    return obj.decode()
UnicodeDecodeError: 'utf-8' codec can't decode byte 0xff in position 0: invalid start byte
ERROR 2020-01-05 21:47:51,979 basehttp 124 "GET /v1/food/show_food HTTP/1.1" 500 111390
ERROR 2020-01-05 21:48:41,921 exception 118 Internal Server Error: /v1/food/show_food
Traceback (most recent call last):
  File "D:\Virtualenvs\wchat_shop\lib\site-packages\django\core\handlers\exception.py", line 35, in inner
    response = get_response(request)
  File "D:\Virtualenvs\wchat_shop\lib\site-packages\django\core\handlers\base.py", line 128, in _get_response
    response = self.process_exception_by_middleware(e, request)
  File "D:\Virtualenvs\wchat_shop\lib\site-packages\django\core\handlers\base.py", line 126, in _get_response
    response = wrapped_callback(request, *callback_args, **callback_kwargs)
  File "D:\Virtualenvs\wchat_shop\lib\site-packages\django\views\decorators\csrf.py", line 54, in wrapped_view
    return view_func(*args, **kwargs)
  File "D:\Virtualenvs\wchat_shop\lib\site-packages\django\views\generic\base.py", line 69, in view
    return self.dispatch(request, *args, **kwargs)
  File "D:\Virtualenvs\wchat_shop\lib\site-packages\rest_framework\views.py", line 505, in dispatch
    response = self.handle_exception(exc)
  File "D:\Virtualenvs\wchat_shop\lib\site-packages\rest_framework\views.py", line 465, in handle_exception
    self.raise_uncaught_exception(exc)
  File "D:\Virtualenvs\wchat_shop\lib\site-packages\rest_framework\views.py", line 476, in raise_uncaught_exception
    raise exc
  File "D:\Virtualenvs\wchat_shop\lib\site-packages\rest_framework\views.py", line 502, in dispatch
    response = handler(request, *args, **kwargs)
  File "C:\Users\www97\Desktop\2020-01\server\api\views\store_view.py", line 15, in get
    'id':obj.id,
AttributeError: 'collections.OrderedDict' object has no attribute 'id'
ERROR 2020-01-05 21:48:41,953 basehttp 124 "GET /v1/food/show_food HTTP/1.1" 500 19287
INFO 2020-01-05 21:49:39,565 basehttp 124 "GET /v1/food/show_food HTTP/1.1" 200 4
ERROR 2020-01-05 21:52:21,188 exception 118 Internal Server Error: /v1/food/show_food
Traceback (most recent call last):
  File "D:\Virtualenvs\wchat_shop\lib\site-packages\django\core\handlers\exception.py", line 35, in inner
    response = get_response(request)
  File "D:\Virtualenvs\wchat_shop\lib\site-packages\django\core\handlers\base.py", line 128, in _get_response
    response = self.process_exception_by_middleware(e, request)
  File "D:\Virtualenvs\wchat_shop\lib\site-packages\django\core\handlers\base.py", line 126, in _get_response
    response = wrapped_callback(request, *callback_args, **callback_kwargs)
  File "D:\Virtualenvs\wchat_shop\lib\site-packages\django\views\decorators\csrf.py", line 54, in wrapped_view
    return view_func(*args, **kwargs)
  File "D:\Virtualenvs\wchat_shop\lib\site-packages\django\views\generic\base.py", line 69, in view
    return self.dispatch(request, *args, **kwargs)
  File "D:\Virtualenvs\wchat_shop\lib\site-packages\rest_framework\views.py", line 505, in dispatch
    response = self.handle_exception(exc)
  File "D:\Virtualenvs\wchat_shop\lib\site-packages\rest_framework\views.py", line 465, in handle_exception
    self.raise_uncaught_exception(exc)
  File "D:\Virtualenvs\wchat_shop\lib\site-packages\rest_framework\views.py", line 476, in raise_uncaught_exception
    raise exc
  File "D:\Virtualenvs\wchat_shop\lib\site-packages\rest_framework\views.py", line 502, in dispatch
    response = handler(request, *args, **kwargs)
  File "C:\Users\www97\Desktop\2020-01\server\api\views\store_view.py", line 15, in get
    print(send_dict[obj[0][0]])
KeyError: 0
ERROR 2020-01-05 21:52:21,217 basehttp 124 "GET /v1/food/show_food HTTP/1.1" 500 19179
ERROR 2020-01-05 21:52:26,371 exception 118 Internal Server Error: /v1/food/show_food
Traceback (most recent call last):
  File "D:\Virtualenvs\wchat_shop\lib\site-packages\django\core\handlers\exception.py", line 35, in inner
    response = get_response(request)
  File "D:\Virtualenvs\wchat_shop\lib\site-packages\django\core\handlers\base.py", line 128, in _get_response
    response = self.process_exception_by_middleware(e, request)
  File "D:\Virtualenvs\wchat_shop\lib\site-packages\django\core\handlers\base.py", line 126, in _get_response
    response = wrapped_callback(request, *callback_args, **callback_kwargs)
  File "D:\Virtualenvs\wchat_shop\lib\site-packages\django\views\decorators\csrf.py", line 54, in wrapped_view
    return view_func(*args, **kwargs)
  File "D:\Virtualenvs\wchat_shop\lib\site-packages\django\views\generic\base.py", line 69, in view
    return self.dispatch(request, *args, **kwargs)
  File "D:\Virtualenvs\wchat_shop\lib\site-packages\rest_framework\views.py", line 505, in dispatch
    response = self.handle_exception(exc)
  File "D:\Virtualenvs\wchat_shop\lib\site-packages\rest_framework\views.py", line 465, in handle_exception
    self.raise_uncaught_exception(exc)
  File "D:\Virtualenvs\wchat_shop\lib\site-packages\rest_framework\views.py", line 476, in raise_uncaught_exception
    raise exc
  File "D:\Virtualenvs\wchat_shop\lib\site-packages\rest_framework\views.py", line 502, in dispatch
    response = handler(request, *args, **kwargs)
  File "C:\Users\www97\Desktop\2020-01\server\api\views\store_view.py", line 15, in get
    print(send_dict[obj[0][0]])
KeyError: 0
ERROR 2020-01-05 21:52:26,391 basehttp 124 "GET /v1/food/show_food HTTP/1.1" 500 19180
ERROR 2020-01-05 21:53:09,205 exception 118 Internal Server Error: /v1/food/show_food
Traceback (most recent call last):
  File "D:\Virtualenvs\wchat_shop\lib\site-packages\django\core\handlers\exception.py", line 35, in inner
    response = get_response(request)
  File "D:\Virtualenvs\wchat_shop\lib\site-packages\django\core\handlers\base.py", line 128, in _get_response
    response = self.process_exception_by_middleware(e, request)
  File "D:\Virtualenvs\wchat_shop\lib\site-packages\django\core\handlers\base.py", line 126, in _get_response
    response = wrapped_callback(request, *callback_args, **callback_kwargs)
  File "D:\Virtualenvs\wchat_shop\lib\site-packages\django\views\decorators\csrf.py", line 54, in wrapped_view
    return view_func(*args, **kwargs)
  File "D:\Virtualenvs\wchat_shop\lib\site-packages\django\views\generic\base.py", line 69, in view
    return self.dispatch(request, *args, **kwargs)
  File "D:\Virtualenvs\wchat_shop\lib\site-packages\rest_framework\views.py", line 505, in dispatch
    response = self.handle_exception(exc)
  File "D:\Virtualenvs\wchat_shop\lib\site-packages\rest_framework\views.py", line 465, in handle_exception
    self.raise_uncaught_exception(exc)
  File "D:\Virtualenvs\wchat_shop\lib\site-packages\rest_framework\views.py", line 476, in raise_uncaught_exception
    raise exc
  File "D:\Virtualenvs\wchat_shop\lib\site-packages\rest_framework\views.py", line 502, in dispatch
    response = handler(request, *args, **kwargs)
  File "C:\Users\www97\Desktop\2020-01\server\api\views\store_view.py", line 16, in get
    print(obj[0])
KeyError: 0
ERROR 2020-01-05 21:53:09,227 basehttp 124 "GET /v1/food/show_food HTTP/1.1" 500 19165
ERROR 2020-01-05 21:53:10,610 exception 118 Internal Server Error: /v1/food/show_food
Traceback (most recent call last):
  File "D:\Virtualenvs\wchat_shop\lib\site-packages\django\core\handlers\exception.py", line 35, in inner
    response = get_response(request)
  File "D:\Virtualenvs\wchat_shop\lib\site-packages\django\core\handlers\base.py", line 128, in _get_response
    response = self.process_exception_by_middleware(e, request)
  File "D:\Virtualenvs\wchat_shop\lib\site-packages\django\core\handlers\base.py", line 126, in _get_response
    response = wrapped_callback(request, *callback_args, **callback_kwargs)
  File "D:\Virtualenvs\wchat_shop\lib\site-packages\django\views\decorators\csrf.py", line 54, in wrapped_view
    return view_func(*args, **kwargs)
  File "D:\Virtualenvs\wchat_shop\lib\site-packages\django\views\generic\base.py", line 69, in view
    return self.dispatch(request, *args, **kwargs)
  File "D:\Virtualenvs\wchat_shop\lib\site-packages\rest_framework\views.py", line 505, in dispatch
    response = self.handle_exception(exc)
  File "D:\Virtualenvs\wchat_shop\lib\site-packages\rest_framework\views.py", line 465, in handle_exception
    self.raise_uncaught_exception(exc)
  File "D:\Virtualenvs\wchat_shop\lib\site-packages\rest_framework\views.py", line 476, in raise_uncaught_exception
    raise exc
  File "D:\Virtualenvs\wchat_shop\lib\site-packages\rest_framework\views.py", line 502, in dispatch
    response = handler(request, *args, **kwargs)
  File "C:\Users\www97\Desktop\2020-01\server\api\views\store_view.py", line 16, in get
    print(obj[0])
KeyError: 0
ERROR 2020-01-05 21:53:10,627 basehttp 124 "GET /v1/food/show_food HTTP/1.1" 500 19165
ERROR 2020-01-05 21:53:40,536 exception 118 Internal Server Error: /v1/food/show_food
Traceback (most recent call last):
  File "D:\Virtualenvs\wchat_shop\lib\site-packages\django\core\handlers\exception.py", line 35, in inner
    response = get_response(request)
  File "D:\Virtualenvs\wchat_shop\lib\site-packages\django\core\handlers\base.py", line 128, in _get_response
    response = self.process_exception_by_middleware(e, request)
  File "D:\Virtualenvs\wchat_shop\lib\site-packages\django\core\handlers\base.py", line 126, in _get_response
    response = wrapped_callback(request, *callback_args, **callback_kwargs)
  File "D:\Virtualenvs\wchat_shop\lib\site-packages\django\views\decorators\csrf.py", line 54, in wrapped_view
    return view_func(*args, **kwargs)
  File "D:\Virtualenvs\wchat_shop\lib\site-packages\django\views\generic\base.py", line 69, in view
    return self.dispatch(request, *args, **kwargs)
  File "D:\Virtualenvs\wchat_shop\lib\site-packages\rest_framework\views.py", line 505, in dispatch
    response = self.handle_exception(exc)
  File "D:\Virtualenvs\wchat_shop\lib\site-packages\rest_framework\views.py", line 465, in handle_exception
    self.raise_uncaught_exception(exc)
  File "D:\Virtualenvs\wchat_shop\lib\site-packages\rest_framework\views.py", line 476, in raise_uncaught_exception
    raise exc
  File "D:\Virtualenvs\wchat_shop\lib\site-packages\rest_framework\views.py", line 502, in dispatch
    response = handler(request, *args, **kwargs)
  File "C:\Users\www97\Desktop\2020-01\server\api\views\store_view.py", line 16, in get
    print(obj.id)
AttributeError: 'collections.OrderedDict' object has no attribute 'id'
ERROR 2020-01-05 21:53:40,559 basehttp 124 "GET /v1/food/show_food HTTP/1.1" 500 19283
INFO 2020-01-05 21:54:42,923 basehttp 124 "GET /v1/food/show_food HTTP/1.1" 200 4
ERROR 2020-01-05 21:56:15,337 exception 118 Internal Server Error: /v1/food/show_food
Traceback (most recent call last):
  File "D:\Virtualenvs\wchat_shop\lib\site-packages\django\core\handlers\exception.py", line 35, in inner
    response = get_response(request)
  File "D:\Virtualenvs\wchat_shop\lib\site-packages\django\core\handlers\base.py", line 128, in _get_response
    response = self.process_exception_by_middleware(e, request)
  File "D:\Virtualenvs\wchat_shop\lib\site-packages\django\core\handlers\base.py", line 126, in _get_response
    response = wrapped_callback(request, *callback_args, **callback_kwargs)
  File "D:\Virtualenvs\wchat_shop\lib\site-packages\django\views\decorators\csrf.py", line 54, in wrapped_view
    return view_func(*args, **kwargs)
  File "D:\Virtualenvs\wchat_shop\lib\site-packages\django\views\generic\base.py", line 69, in view
    return self.dispatch(request, *args, **kwargs)
  File "D:\Virtualenvs\wchat_shop\lib\site-packages\rest_framework\views.py", line 505, in dispatch
    response = self.handle_exception(exc)
  File "D:\Virtualenvs\wchat_shop\lib\site-packages\rest_framework\views.py", line 465, in handle_exception
    self.raise_uncaught_exception(exc)
  File "D:\Virtualenvs\wchat_shop\lib\site-packages\rest_framework\views.py", line 476, in raise_uncaught_exception
    raise exc
  File "D:\Virtualenvs\wchat_shop\lib\site-packages\rest_framework\views.py", line 502, in dispatch
    response = handler(request, *args, **kwargs)
  File "C:\Users\www97\Desktop\2020-01\server\api\views\store_view.py", line 16, in get
    print(obj.id)
AttributeError: 'collections.OrderedDict' object has no attribute 'id'
ERROR 2020-01-05 21:56:15,389 basehttp 124 "GET /v1/food/show_food HTTP/1.1" 500 20541
ERROR 2020-01-05 21:59:17,950 exception 118 Internal Server Error: /v1/food/show_food
Traceback (most recent call last):
  File "D:\Virtualenvs\wchat_shop\lib\site-packages\django\core\handlers\exception.py", line 35, in inner
    response = get_response(request)
  File "D:\Virtualenvs\wchat_shop\lib\site-packages\django\core\handlers\base.py", line 128, in _get_response
    response = self.process_exception_by_middleware(e, request)
  File "D:\Virtualenvs\wchat_shop\lib\site-packages\django\core\handlers\base.py", line 126, in _get_response
    response = wrapped_callback(request, *callback_args, **callback_kwargs)
  File "D:\Virtualenvs\wchat_shop\lib\site-packages\django\views\decorators\csrf.py", line 54, in wrapped_view
    return view_func(*args, **kwargs)
  File "D:\Virtualenvs\wchat_shop\lib\site-packages\django\views\generic\base.py", line 69, in view
    return self.dispatch(request, *args, **kwargs)
  File "D:\Virtualenvs\wchat_shop\lib\site-packages\rest_framework\views.py", line 505, in dispatch
    response = self.handle_exception(exc)
  File "D:\Virtualenvs\wchat_shop\lib\site-packages\rest_framework\views.py", line 465, in handle_exception
    self.raise_uncaught_exception(exc)
  File "D:\Virtualenvs\wchat_shop\lib\site-packages\rest_framework\views.py", line 476, in raise_uncaught_exception
    raise exc
  File "D:\Virtualenvs\wchat_shop\lib\site-packages\rest_framework\views.py", line 502, in dispatch
    response = handler(request, *args, **kwargs)
  File "C:\Users\www97\Desktop\2020-01\server\api\views\store_view.py", line 19, in get
    send_dict['img'] = obj['img']
KeyError: 'img'
ERROR 2020-01-05 21:59:18,065 basehttp 124 "GET /v1/food/show_food HTTP/1.1" 500 20447
INFO 2020-01-05 21:59:41,165 basehttp 124 "GET /v1/food/show_food HTTP/1.1" 200 4
INFO 2020-01-05 22:00:02,051 basehttp 124 "GET /v1/food/show_food HTTP/1.1" 200 4
INFO 2020-01-05 22:17:15,148 basehttp 124 "GET /v1/food/show_food HTTP/1.1" 200 175
INFO 2020-01-05 22:18:08,661 basehttp 124 "GET /v1/food/show_food HTTP/1.1" 200 175
INFO 2020-01-05 22:19:04,357 basehttp 124 "GET /v1/food/show_food HTTP/1.1" 200 175
INFO 2020-01-05 22:19:49,009 basehttp 124 "GET /v1/food/show_food HTTP/1.1" 200 415
ERROR 2020-01-05 22:32:12,932 exception 118 Internal Server Error: /v1/food/show_food
Traceback (most recent call last):
  File "D:\Virtualenvs\wchat_shop\lib\site-packages\django\core\handlers\exception.py", line 35, in inner
    response = get_response(request)
  File "D:\Virtualenvs\wchat_shop\lib\site-packages\django\core\handlers\base.py", line 128, in _get_response
    response = self.process_exception_by_middleware(e, request)
  File "D:\Virtualenvs\wchat_shop\lib\site-packages\django\core\handlers\base.py", line 126, in _get_response
    response = wrapped_callback(request, *callback_args, **callback_kwargs)
  File "D:\Virtualenvs\wchat_shop\lib\site-packages\django\views\decorators\csrf.py", line 54, in wrapped_view
    return view_func(*args, **kwargs)
  File "D:\Virtualenvs\wchat_shop\lib\site-packages\django\views\generic\base.py", line 69, in view
    return self.dispatch(request, *args, **kwargs)
  File "D:\Virtualenvs\wchat_shop\lib\site-packages\rest_framework\views.py", line 505, in dispatch
    response = self.handle_exception(exc)
  File "D:\Virtualenvs\wchat_shop\lib\site-packages\rest_framework\views.py", line 465, in handle_exception
    self.raise_uncaught_exception(exc)
  File "D:\Virtualenvs\wchat_shop\lib\site-packages\rest_framework\views.py", line 476, in raise_uncaught_exception
    raise exc
  File "D:\Virtualenvs\wchat_shop\lib\site-packages\rest_framework\views.py", line 502, in dispatch
    response = handler(request, *args, **kwargs)
  File "C:\Users\www97\Desktop\2020-01\server\api\views\store_view.py", line 17, in get
    print(obj['img'].decode('utf-8'))
AttributeError: 'str' object has no attribute 'decode'
ERROR 2020-01-05 22:32:13,034 basehttp 124 "GET /v1/food/show_food HTTP/1.1" 500 20529
INFO 2020-01-05 22:32:35,366 basehttp 124 "GET /v1/food/show_food HTTP/1.1" 200 415
INFO 2020-01-05 22:34:18,611 basehttp 124 "GET /v1/food/show_food HTTP/1.1" 200 503
INFO 2020-01-06 08:56:03,504 basehttp 124 "GET /v1/food/show_food HTTP/1.1" 200 503
INFO 2020-01-06 08:56:58,115 basehttp 124 "GET /v1/food/show_food HTTP/1.1" 200 407
INFO 2020-01-06 09:24:14,454 basehttp 124 "GET /static/img/test.jpg HTTP/1.1" 200 28286
INFO 2020-01-06 09:24:39,326 basehttp 124 "GET /static/img/test.jpg HTTP/1.1" 200 28286
INFO 2020-01-06 09:26:34,554 basehttp 124 "GET /static/img/test.jpg HTTP/1.1" 200 28286
INFO 2020-01-06 09:28:11,573 basehttp 124 "GET /static/img/test.jpg HTTP/1.1" 200 28286
INFO 2020-01-06 09:29:05,362 basehttp 124 "GET /static/img/test.jpg HTTP/1.1" 200 28286
INFO 2020-01-06 09:29:33,975 basehttp 124 "GET /static/img/test.jpg HTTP/1.1" 200 28286
INFO 2020-01-06 09:37:52,893 basehttp 124 "GET /v1/food/show_food HTTP/1.1" 200 415
INFO 2020-01-06 09:38:07,172 basehttp 124 "GET /static/img/Yellow_pheasant.jpg HTTP/1.1" 200 344943
INFO 2020-01-06 09:49:55,598 basehttp 124 "GET /v1/food/show_food HTTP/1.1" 200 415
ERROR 2020-01-06 09:52:44,774 exception 118 Internal Server Error: /v1/food/show_food
Traceback (most recent call last):
  File "D:\Virtualenvs\wchat_shop\lib\site-packages\django\core\handlers\exception.py", line 35, in inner
    response = get_response(request)
  File "D:\Virtualenvs\wchat_shop\lib\site-packages\django\core\handlers\base.py", line 128, in _get_response
    response = self.process_exception_by_middleware(e, request)
  File "D:\Virtualenvs\wchat_shop\lib\site-packages\django\core\handlers\base.py", line 126, in _get_response
    response = wrapped_callback(request, *callback_args, **callback_kwargs)
  File "D:\Virtualenvs\wchat_shop\lib\site-packages\django\views\decorators\csrf.py", line 54, in wrapped_view
    return view_func(*args, **kwargs)
  File "D:\Virtualenvs\wchat_shop\lib\site-packages\django\views\generic\base.py", line 69, in view
    return self.dispatch(request, *args, **kwargs)
  File "D:\Virtualenvs\wchat_shop\lib\site-packages\rest_framework\views.py", line 505, in dispatch
    response = self.handle_exception(exc)
  File "D:\Virtualenvs\wchat_shop\lib\site-packages\rest_framework\views.py", line 465, in handle_exception
    self.raise_uncaught_exception(exc)
  File "D:\Virtualenvs\wchat_shop\lib\site-packages\rest_framework\views.py", line 476, in raise_uncaught_exception
    raise exc
  File "D:\Virtualenvs\wchat_shop\lib\site-packages\rest_framework\views.py", line 502, in dispatch
    response = handler(request, *args, **kwargs)
  File "C:\Users\www97\Desktop\2020-01\server\api\views\store_view.py", line 25, in get
    send_dict['category'] = obj['category_id']
KeyError: 'category_id'
ERROR 2020-01-06 09:52:45,006 basehttp 124 "GET /v1/food/show_food HTTP/1.1" 500 20533
INFO 2020-01-06 09:53:06,039 basehttp 124 "GET /v1/food/show_food HTTP/1.1" 200 467
ERROR 2020-01-06 09:55:42,342 exception 118 Internal Server Error: /v1/food/show_food
Traceback (most recent call last):
  File "D:\Virtualenvs\wchat_shop\lib\site-packages\django\core\handlers\exception.py", line 35, in inner
    response = get_response(request)
  File "D:\Virtualenvs\wchat_shop\lib\site-packages\django\core\handlers\base.py", line 128, in _get_response
    response = self.process_exception_by_middleware(e, request)
  File "D:\Virtualenvs\wchat_shop\lib\site-packages\django\core\handlers\base.py", line 126, in _get_response
    response = wrapped_callback(request, *callback_args, **callback_kwargs)
  File "D:\Virtualenvs\wchat_shop\lib\site-packages\django\views\decorators\csrf.py", line 54, in wrapped_view
    return view_func(*args, **kwargs)
  File "D:\Virtualenvs\wchat_shop\lib\site-packages\django\views\generic\base.py", line 69, in view
    return self.dispatch(request, *args, **kwargs)
  File "D:\Virtualenvs\wchat_shop\lib\site-packages\rest_framework\views.py", line 505, in dispatch
    response = self.handle_exception(exc)
  File "D:\Virtualenvs\wchat_shop\lib\site-packages\rest_framework\views.py", line 465, in handle_exception
    self.raise_uncaught_exception(exc)
  File "D:\Virtualenvs\wchat_shop\lib\site-packages\rest_framework\views.py", line 476, in raise_uncaught_exception
    raise exc
  File "D:\Virtualenvs\wchat_shop\lib\site-packages\rest_framework\views.py", line 502, in dispatch
    response = handler(request, *args, **kwargs)
  File "C:\Users\www97\Desktop\2020-01\server\api\views\store_view.py", line 32, in get
    send_dict['category'] = category_dict[obj['category']]
KeyError: 1
ERROR 2020-01-06 09:55:42,442 basehttp 124 "GET /v1/food/show_food HTTP/1.1" 500 20520
INFO 2020-01-06 09:56:16,463 basehttp 124 "GET /v1/food/show_food HTTP/1.1" 200 495
INFO 2020-01-06 09:56:54,961 basehttp 124 "GET /static/img/Yellow_pheasant.jpg HTTP/1.1" 200 344943
INFO 2020-01-06 09:56:57,214 basehttp 124 "GET /static/img/Peppers_potatoes.jpg HTTP/1.1" 200 28286
ERROR 2020-01-06 11:09:14,431 exception 118 Internal Server Error: /v1/food/show_food
Traceback (most recent call last):
  File "D:\Virtualenvs\wchat_shop\lib\site-packages\rest_framework\views.py", line 502, in dispatch
    response = handler(request, *args, **kwargs)
  File "C:\Users\www97\Desktop\2020-01\server\api\views\store_view.py", line 25, in get
    cache('food_list', food_ser_list)
TypeError: 'DefaultCacheProxy' object is not callable

During handling of the above exception, another exception occurred:

Traceback (most recent call last):
  File "D:\Virtualenvs\wchat_shop\lib\site-packages\rest_framework\settings.py", line 177, in import_from_string
    return import_string(val)
  File "D:\Virtualenvs\wchat_shop\lib\site-packages\django\utils\module_loading.py", line 17, in import_string
    module = import_module(module_path)
  File "D:\Virtualenvs\wchat_shop\lib\importlib\__init__.py", line 126, in import_module
    return _bootstrap._gcd_import(name[level:], package, level)
  File "<frozen importlib._bootstrap>", line 994, in _gcd_import
  File "<frozen importlib._bootstrap>", line 971, in _find_and_load
  File "<frozen importlib._bootstrap>", line 941, in _find_and_load_unlocked
  File "<frozen importlib._bootstrap>", line 219, in _call_with_frames_removed
  File "<frozen importlib._bootstrap>", line 994, in _gcd_import
  File "<frozen importlib._bootstrap>", line 971, in _find_and_load
  File "<frozen importlib._bootstrap>", line 953, in _find_and_load_unlocked
ModuleNotFoundError: No module named 'utils'

During handling of the above exception, another exception occurred:

Traceback (most recent call last):
  File "D:\Virtualenvs\wchat_shop\lib\site-packages\django\core\handlers\exception.py", line 35, in inner
    response = get_response(request)
  File "D:\Virtualenvs\wchat_shop\lib\site-packages\django\core\handlers\base.py", line 128, in _get_response
    response = self.process_exception_by_middleware(e, request)
  File "D:\Virtualenvs\wchat_shop\lib\site-packages\django\core\handlers\base.py", line 126, in _get_response
    response = wrapped_callback(request, *callback_args, **callback_kwargs)
  File "D:\Virtualenvs\wchat_shop\lib\site-packages\django\views\decorators\csrf.py", line 54, in wrapped_view
    return view_func(*args, **kwargs)
  File "D:\Virtualenvs\wchat_shop\lib\site-packages\django\views\generic\base.py", line 69, in view
    return self.dispatch(request, *args, **kwargs)
  File "D:\Virtualenvs\wchat_shop\lib\site-packages\rest_framework\views.py", line 505, in dispatch
    response = self.handle_exception(exc)
  File "D:\Virtualenvs\wchat_shop\lib\site-packages\rest_framework\views.py", line 459, in handle_exception
    exception_handler = self.get_exception_handler()
  File "D:\Virtualenvs\wchat_shop\lib\site-packages\rest_framework\views.py", line 298, in get_exception_handler
    return self.settings.EXCEPTION_HANDLER
  File "D:\Virtualenvs\wchat_shop\lib\site-packages\rest_framework\settings.py", line 220, in __getattr__
    val = perform_import(val, attr)
  File "D:\Virtualenvs\wchat_shop\lib\site-packages\rest_framework\settings.py", line 166, in perform_import
    return import_from_string(val, setting_name)
  File "D:\Virtualenvs\wchat_shop\lib\site-packages\rest_framework\settings.py", line 180, in import_from_string
    raise ImportError(msg)
ImportError: Could not import 'utils.exception.custom_exception_handler' for API setting 'EXCEPTION_HANDLER'. ModuleNotFoundError: No module named 'utils'.
ERROR 2020-01-06 11:09:14,904 basehttp 124 "GET /v1/food/show_food HTTP/1.1" 500 135811
ERROR 2020-01-06 11:09:17,196 exception 118 Internal Server Error: /v1/food/show_food
Traceback (most recent call last):
  File "D:\Virtualenvs\wchat_shop\lib\site-packages\rest_framework\views.py", line 502, in dispatch
    response = handler(request, *args, **kwargs)
  File "C:\Users\www97\Desktop\2020-01\server\api\views\store_view.py", line 25, in get
    cache('food_list', food_ser_list)
TypeError: 'DefaultCacheProxy' object is not callable

During handling of the above exception, another exception occurred:

Traceback (most recent call last):
  File "D:\Virtualenvs\wchat_shop\lib\site-packages\rest_framework\settings.py", line 177, in import_from_string
    return import_string(val)
  File "D:\Virtualenvs\wchat_shop\lib\site-packages\django\utils\module_loading.py", line 17, in import_string
    module = import_module(module_path)
  File "D:\Virtualenvs\wchat_shop\lib\importlib\__init__.py", line 126, in import_module
    return _bootstrap._gcd_import(name[level:], package, level)
  File "<frozen importlib._bootstrap>", line 994, in _gcd_import
  File "<frozen importlib._bootstrap>", line 971, in _find_and_load
  File "<frozen importlib._bootstrap>", line 941, in _find_and_load_unlocked
  File "<frozen importlib._bootstrap>", line 219, in _call_with_frames_removed
  File "<frozen importlib._bootstrap>", line 994, in _gcd_import
  File "<frozen importlib._bootstrap>", line 971, in _find_and_load
  File "<frozen importlib._bootstrap>", line 953, in _find_and_load_unlocked
ModuleNotFoundError: No module named 'utils'

During handling of the above exception, another exception occurred:

Traceback (most recent call last):
  File "D:\Virtualenvs\wchat_shop\lib\site-packages\django\core\handlers\exception.py", line 35, in inner
    response = get_response(request)
  File "D:\Virtualenvs\wchat_shop\lib\site-packages\django\core\handlers\base.py", line 128, in _get_response
    response = self.process_exception_by_middleware(e, request)
  File "D:\Virtualenvs\wchat_shop\lib\site-packages\django\core\handlers\base.py", line 126, in _get_response
    response = wrapped_callback(request, *callback_args, **callback_kwargs)
  File "D:\Virtualenvs\wchat_shop\lib\site-packages\django\views\decorators\csrf.py", line 54, in wrapped_view
    return view_func(*args, **kwargs)
  File "D:\Virtualenvs\wchat_shop\lib\site-packages\django\views\generic\base.py", line 69, in view
    return self.dispatch(request, *args, **kwargs)
  File "D:\Virtualenvs\wchat_shop\lib\site-packages\rest_framework\views.py", line 505, in dispatch
    response = self.handle_exception(exc)
  File "D:\Virtualenvs\wchat_shop\lib\site-packages\rest_framework\views.py", line 459, in handle_exception
    exception_handler = self.get_exception_handler()
  File "D:\Virtualenvs\wchat_shop\lib\site-packages\rest_framework\views.py", line 298, in get_exception_handler
    return self.settings.EXCEPTION_HANDLER
  File "D:\Virtualenvs\wchat_shop\lib\site-packages\rest_framework\settings.py", line 220, in __getattr__
    val = perform_import(val, attr)
  File "D:\Virtualenvs\wchat_shop\lib\site-packages\rest_framework\settings.py", line 166, in perform_import
    return import_from_string(val, setting_name)
  File "D:\Virtualenvs\wchat_shop\lib\site-packages\rest_framework\settings.py", line 180, in import_from_string
    raise ImportError(msg)
ImportError: Could not import 'utils.exception.custom_exception_handler' for API setting 'EXCEPTION_HANDLER'. ModuleNotFoundError: No module named 'utils'.
ERROR 2020-01-06 11:09:17,510 basehttp 124 "GET /v1/food/show_food HTTP/1.1" 500 135811
INFO 2020-01-06 11:09:52,608 basehttp 124 "GET /v1/food/show_food HTTP/1.1" 200 495
INFO 2020-01-06 11:10:28,060 basehttp 124 "GET /static/img/Yellow_pheasant.jpg HTTP/1.1" 200 344943
INFO 2020-01-06 11:11:06,853 basehttp 124 "GET /v1/food/show_food HTTP/1.1" 200 495
INFO 2020-01-06 11:11:09,250 basehttp 124 "GET /v1/food/show_food HTTP/1.1" 200 495
INFO 2020-01-06 11:11:11,334 basehttp 124 "GET /v1/food/show_food HTTP/1.1" 200 495
INFO 2020-01-06 11:11:13,347 basehttp 124 "GET /v1/food/show_food HTTP/1.1" 200 495
ERROR 2020-01-06 16:31:38,561 exception 118 Internal Server Error: /v1/food/show_detail
Traceback (most recent call last):
  File "D:\Virtualenvs\wchat_shop\lib\site-packages\rest_framework\views.py", line 502, in dispatch
    response = handler(request, *args, **kwargs)
  File "C:\Users\www97\Desktop\2020-01\server\api\views\store_view.py", line 52, in post
    'food_dec': food_ser['detail']['dec'],
TypeError: 'int' object is not subscriptable

During handling of the above exception, another exception occurred:

Traceback (most recent call last):
  File "D:\Virtualenvs\wchat_shop\lib\site-packages\rest_framework\settings.py", line 177, in import_from_string
    return import_string(val)
  File "D:\Virtualenvs\wchat_shop\lib\site-packages\django\utils\module_loading.py", line 17, in import_string
    module = import_module(module_path)
  File "D:\Virtualenvs\wchat_shop\lib\importlib\__init__.py", line 126, in import_module
    return _bootstrap._gcd_import(name[level:], package, level)
  File "<frozen importlib._bootstrap>", line 994, in _gcd_import
  File "<frozen importlib._bootstrap>", line 971, in _find_and_load
  File "<frozen importlib._bootstrap>", line 941, in _find_and_load_unlocked
  File "<frozen importlib._bootstrap>", line 219, in _call_with_frames_removed
  File "<frozen importlib._bootstrap>", line 994, in _gcd_import
  File "<frozen importlib._bootstrap>", line 971, in _find_and_load
  File "<frozen importlib._bootstrap>", line 953, in _find_and_load_unlocked
ModuleNotFoundError: No module named 'utils'

During handling of the above exception, another exception occurred:

Traceback (most recent call last):
  File "D:\Virtualenvs\wchat_shop\lib\site-packages\django\core\handlers\exception.py", line 35, in inner
    response = get_response(request)
  File "D:\Virtualenvs\wchat_shop\lib\site-packages\django\core\handlers\base.py", line 128, in _get_response
    response = self.process_exception_by_middleware(e, request)
  File "D:\Virtualenvs\wchat_shop\lib\site-packages\django\core\handlers\base.py", line 126, in _get_response
    response = wrapped_callback(request, *callback_args, **callback_kwargs)
  File "D:\Virtualenvs\wchat_shop\lib\site-packages\django\views\decorators\csrf.py", line 54, in wrapped_view
    return view_func(*args, **kwargs)
  File "D:\Virtualenvs\wchat_shop\lib\site-packages\django\views\generic\base.py", line 69, in view
    return self.dispatch(request, *args, **kwargs)
  File "D:\Virtualenvs\wchat_shop\lib\site-packages\rest_framework\views.py", line 505, in dispatch
    response = self.handle_exception(exc)
  File "D:\Virtualenvs\wchat_shop\lib\site-packages\rest_framework\views.py", line 459, in handle_exception
    exception_handler = self.get_exception_handler()
  File "D:\Virtualenvs\wchat_shop\lib\site-packages\rest_framework\views.py", line 298, in get_exception_handler
    return self.settings.EXCEPTION_HANDLER
  File "D:\Virtualenvs\wchat_shop\lib\site-packages\rest_framework\settings.py", line 220, in __getattr__
    val = perform_import(val, attr)
  File "D:\Virtualenvs\wchat_shop\lib\site-packages\rest_framework\settings.py", line 166, in perform_import
    return import_from_string(val, setting_name)
  File "D:\Virtualenvs\wchat_shop\lib\site-packages\rest_framework\settings.py", line 180, in import_from_string
    raise ImportError(msg)
ImportError: Could not import 'utils.exception.custom_exception_handler' for API setting 'EXCEPTION_HANDLER'. ModuleNotFoundError: No module named 'utils'.
ERROR 2020-01-06 16:31:39,050 basehttp 124 "POST /v1/food/show_detail HTTP/1.1" 500 135683
ERROR 2020-01-06 16:32:44,031 exception 118 Internal Server Error: /v1/food/show_detail
Traceback (most recent call last):
  File "D:\Virtualenvs\wchat_shop\lib\site-packages\rest_framework\views.py", line 502, in dispatch
    response = handler(request, *args, **kwargs)
  File "C:\Users\www97\Desktop\2020-01\server\api\views\store_view.py", line 52, in post
    'food_dec': food_ser['detail']['dec'],
TypeError: 'int' object is not subscriptable

During handling of the above exception, another exception occurred:

Traceback (most recent call last):
  File "D:\Virtualenvs\wchat_shop\lib\site-packages\rest_framework\settings.py", line 177, in import_from_string
    return import_string(val)
  File "D:\Virtualenvs\wchat_shop\lib\site-packages\django\utils\module_loading.py", line 17, in import_string
    module = import_module(module_path)
  File "D:\Virtualenvs\wchat_shop\lib\importlib\__init__.py", line 126, in import_module
    return _bootstrap._gcd_import(name[level:], package, level)
  File "<frozen importlib._bootstrap>", line 994, in _gcd_import
  File "<frozen importlib._bootstrap>", line 971, in _find_and_load
  File "<frozen importlib._bootstrap>", line 941, in _find_and_load_unlocked
  File "<frozen importlib._bootstrap>", line 219, in _call_with_frames_removed
  File "<frozen importlib._bootstrap>", line 994, in _gcd_import
  File "<frozen importlib._bootstrap>", line 971, in _find_and_load
  File "<frozen importlib._bootstrap>", line 953, in _find_and_load_unlocked
ModuleNotFoundError: No module named 'utils'

During handling of the above exception, another exception occurred:

Traceback (most recent call last):
  File "D:\Virtualenvs\wchat_shop\lib\site-packages\django\core\handlers\exception.py", line 35, in inner
    response = get_response(request)
  File "D:\Virtualenvs\wchat_shop\lib\site-packages\django\core\handlers\base.py", line 128, in _get_response
    response = self.process_exception_by_middleware(e, request)
  File "D:\Virtualenvs\wchat_shop\lib\site-packages\django\core\handlers\base.py", line 126, in _get_response
    response = wrapped_callback(request, *callback_args, **callback_kwargs)
  File "D:\Virtualenvs\wchat_shop\lib\site-packages\django\views\decorators\csrf.py", line 54, in wrapped_view
    return view_func(*args, **kwargs)
  File "D:\Virtualenvs\wchat_shop\lib\site-packages\django\views\generic\base.py", line 69, in view
    return self.dispatch(request, *args, **kwargs)
  File "D:\Virtualenvs\wchat_shop\lib\site-packages\rest_framework\views.py", line 505, in dispatch
    response = self.handle_exception(exc)
  File "D:\Virtualenvs\wchat_shop\lib\site-packages\rest_framework\views.py", line 459, in handle_exception
    exception_handler = self.get_exception_handler()
  File "D:\Virtualenvs\wchat_shop\lib\site-packages\rest_framework\views.py", line 298, in get_exception_handler
    return self.settings.EXCEPTION_HANDLER
  File "D:\Virtualenvs\wchat_shop\lib\site-packages\rest_framework\settings.py", line 220, in __getattr__
    val = perform_import(val, attr)
  File "D:\Virtualenvs\wchat_shop\lib\site-packages\rest_framework\settings.py", line 166, in perform_import
    return import_from_string(val, setting_name)
  File "D:\Virtualenvs\wchat_shop\lib\site-packages\rest_framework\settings.py", line 180, in import_from_string
    raise ImportError(msg)
ImportError: Could not import 'utils.exception.custom_exception_handler' for API setting 'EXCEPTION_HANDLER'. ModuleNotFoundError: No module named 'utils'.
ERROR 2020-01-06 16:32:45,002 basehttp 124 "POST /v1/food/show_detail HTTP/1.1" 500 135684
INFO 2020-01-06 16:44:15,553 basehttp 124 "GET /static/img/Yellow_pheasant.jpg HTTP/1.1" 200 344943
INFO 2020-01-06 16:44:19,201 basehttp 124 "GET /v1/food/show_food HTTP/1.1" 200 495
INFO 2020-01-06 17:04:48,349 basehttp 124 "GET /v1/food/show_food HTTP/1.1" 200 559
INFO 2020-01-06 17:06:43,246 basehttp 124 "GET /admin/ HTTP/1.1" 200 9341
INFO 2020-01-06 17:06:43,403 basehttp 124 "GET /static/admin/css/dashboard.css HTTP/1.1" 304 0
INFO 2020-01-06 17:06:43,406 basehttp 124 "GET /static/admin/css/base.css HTTP/1.1" 304 0
INFO 2020-01-06 17:06:43,408 basehttp 124 "GET /static/admin/css/responsive.css HTTP/1.1" 304 0
INFO 2020-01-06 17:06:43,467 basehttp 124 "GET /static/admin/css/fonts.css HTTP/1.1" 304 0
INFO 2020-01-06 17:06:43,518 basehttp 124 "GET /static/admin/img/icon-changelink.svg HTTP/1.1" 304 0
INFO 2020-01-06 17:06:43,520 basehttp 124 "GET /static/admin/img/icon-addlink.svg HTTP/1.1" 304 0
INFO 2020-01-06 17:06:43,755 basehttp 124 "GET /static/admin/fonts/Roboto-Light-webfont.woff HTTP/1.1" 304 0
INFO 2020-01-06 17:06:43,767 basehttp 124 "GET /static/admin/fonts/Roboto-Bold-webfont.woff HTTP/1.1" 304 0
INFO 2020-01-06 17:06:43,768 basehttp 124 "GET /static/admin/fonts/Roboto-Regular-webfont.woff HTTP/1.1" 304 0
WARNING 2020-01-06 17:06:43,797 base 93 Not Found: /favicon.ico
WARNING 2020-01-06 17:06:43,801 basehttp 124 "GET /favicon.ico HTTP/1.1" 404 2333
INFO 2020-01-06 17:06:50,403 basehttp 124 "GET /admin/api/active/add/ HTTP/1.1" 200 7341
INFO 2020-01-06 17:06:50,502 basehttp 124 "GET /static/admin/css/forms.css HTTP/1.1" 304 0
INFO 2020-01-06 17:06:50,504 basehttp 124 "GET /static/admin/js/jquery.init.js HTTP/1.1" 304 0
INFO 2020-01-06 17:06:50,525 basehttp 124 "GET /static/admin/js/vendor/jquery/jquery.js HTTP/1.1" 304 0
INFO 2020-01-06 17:06:50,526 basehttp 124 "GET /static/admin/js/admin/RelatedObjectLookups.js HTTP/1.1" 304 0
INFO 2020-01-06 17:06:50,532 basehttp 124 "GET /static/admin/js/core.js HTTP/1.1" 304 0
INFO 2020-01-06 17:06:50,542 basehttp 124 "GET /static/admin/js/actions.js HTTP/1.1" 304 0
INFO 2020-01-06 17:06:50,565 basehttp 124 "GET /static/admin/js/urlify.js HTTP/1.1" 304 0
INFO 2020-01-06 17:06:50,567 basehttp 124 "GET /static/admin/js/prepopulate.js HTTP/1.1" 304 0
INFO 2020-01-06 17:06:50,570 basehttp 124 "GET /static/admin/js/vendor/xregexp/xregexp.js HTTP/1.1" 304 0
INFO 2020-01-06 17:06:50,601 basehttp 124 "GET /admin/jsi18n/ HTTP/1.1" 200 3185
INFO 2020-01-06 17:06:50,640 basehttp 124 "GET /static/admin/css/widgets.css HTTP/1.1" 304 0
INFO 2020-01-06 17:06:50,644 basehttp 124 "GET /static/admin/js/change_form.js HTTP/1.1" 304 0
INFO 2020-01-06 17:06:50,685 basehttp 124 "GET /static/admin/js/prepopulate_init.js HTTP/1.1" 304 0
INFO 2020-01-06 17:06:50,686 basehttp 124 "GET /static/admin/img/icon-deletelink.svg HTTP/1.1" 304 0
INFO 2020-01-06 17:20:32,869 basehttp 124 "POST /admin/api/active/add/ HTTP/1.1" 302 0
INFO 2020-01-06 17:20:33,278 basehttp 124 "GET /admin/api/active/ HTTP/1.1" 200 4560
INFO 2020-01-06 17:20:33,324 basehttp 124 "GET /static/admin/css/changelists.css HTTP/1.1" 304 0
INFO 2020-01-06 17:20:33,366 basehttp 124 "GET /admin/jsi18n/ HTTP/1.1" 200 3185
INFO 2020-01-06 17:20:33,421 basehttp 124 "GET /static/admin/img/icon-yes.svg HTTP/1.1" 304 0
INFO 2020-01-06 17:20:33,425 basehttp 124 "GET /static/admin/img/tooltag-add.svg HTTP/1.1" 304 0
INFO 2020-01-06 17:23:14,341 basehttp 124 "GET /v1/food/show_food HTTP/1.1" 200 559
ERROR 2020-01-06 17:54:37,368 exception 118 Internal Server Error: /v1/food/show_food
Traceback (most recent call last):
  File "D:\Virtualenvs\wchat_shop\lib\site-packages\rest_framework\views.py", line 502, in dispatch
    response = handler(request, *args, **kwargs)
  File "C:\Users\www97\Desktop\2020-01\server\api\views\store_view.py", line 23, in get
    data_list = CategoryModelSerializer(data=cat_data, many=True).data
  File "D:\Virtualenvs\wchat_shop\lib\site-packages\rest_framework\serializers.py", line 760, in data
    ret = super().data
  File "D:\Virtualenvs\wchat_shop\lib\site-packages\rest_framework\serializers.py", line 256, in data
    raise AssertionError(msg)
AssertionError: When a serializer is passed a `data` keyword argument you must call `.is_valid()` before attempting to access the serialized `.data` representation.
You should either call `.is_valid()` first, or access `.initial_data` instead.

During handling of the above exception, another exception occurred:

Traceback (most recent call last):
  File "D:\Virtualenvs\wchat_shop\lib\site-packages\rest_framework\settings.py", line 177, in import_from_string
    return import_string(val)
  File "D:\Virtualenvs\wchat_shop\lib\site-packages\django\utils\module_loading.py", line 17, in import_string
    module = import_module(module_path)
  File "D:\Virtualenvs\wchat_shop\lib\importlib\__init__.py", line 126, in import_module
    return _bootstrap._gcd_import(name[level:], package, level)
  File "<frozen importlib._bootstrap>", line 994, in _gcd_import
  File "<frozen importlib._bootstrap>", line 971, in _find_and_load
  File "<frozen importlib._bootstrap>", line 941, in _find_and_load_unlocked
  File "<frozen importlib._bootstrap>", line 219, in _call_with_frames_removed
  File "<frozen importlib._bootstrap>", line 994, in _gcd_import
  File "<frozen importlib._bootstrap>", line 971, in _find_and_load
  File "<frozen importlib._bootstrap>", line 953, in _find_and_load_unlocked
ModuleNotFoundError: No module named 'utils'

During handling of the above exception, another exception occurred:

Traceback (most recent call last):
  File "D:\Virtualenvs\wchat_shop\lib\site-packages\django\core\handlers\exception.py", line 35, in inner
    response = get_response(request)
  File "D:\Virtualenvs\wchat_shop\lib\site-packages\django\core\handlers\base.py", line 128, in _get_response
    response = self.process_exception_by_middleware(e, request)
  File "D:\Virtualenvs\wchat_shop\lib\site-packages\django\core\handlers\base.py", line 126, in _get_response
    response = wrapped_callback(request, *callback_args, **callback_kwargs)
  File "D:\Virtualenvs\wchat_shop\lib\site-packages\django\views\decorators\csrf.py", line 54, in wrapped_view
    return view_func(*args, **kwargs)
  File "D:\Virtualenvs\wchat_shop\lib\site-packages\django\views\generic\base.py", line 69, in view
    return self.dispatch(request, *args, **kwargs)
  File "D:\Virtualenvs\wchat_shop\lib\site-packages\rest_framework\views.py", line 505, in dispatch
    response = self.handle_exception(exc)
  File "D:\Virtualenvs\wchat_shop\lib\site-packages\rest_framework\views.py", line 459, in handle_exception
    exception_handler = self.get_exception_handler()
  File "D:\Virtualenvs\wchat_shop\lib\site-packages\rest_framework\views.py", line 298, in get_exception_handler
    return self.settings.EXCEPTION_HANDLER
  File "D:\Virtualenvs\wchat_shop\lib\site-packages\rest_framework\settings.py", line 220, in __getattr__
    val = perform_import(val, attr)
  File "D:\Virtualenvs\wchat_shop\lib\site-packages\rest_framework\settings.py", line 166, in perform_import
    return import_from_string(val, setting_name)
  File "D:\Virtualenvs\wchat_shop\lib\site-packages\rest_framework\settings.py", line 180, in import_from_string
    raise ImportError(msg)
ImportError: Could not import 'utils.exception.custom_exception_handler' for API setting 'EXCEPTION_HANDLER'. ModuleNotFoundError: No module named 'utils'.
ERROR 2020-01-06 17:54:37,780 basehttp 124 "GET /v1/food/show_food HTTP/1.1" 500 143600
ERROR 2020-01-06 17:59:12,152 exception 118 Internal Server Error: /v1/food/show_food
Traceback (most recent call last):
  File "D:\Virtualenvs\wchat_shop\lib\site-packages\rest_framework\views.py", line 502, in dispatch
    response = handler(request, *args, **kwargs)
  File "C:\Users\www97\Desktop\2020-01\server\api\views\store_view.py", line 23, in get
    data_list = CategoryModelSerializer(cat_data, many=True).data
  File "D:\Virtualenvs\wchat_shop\lib\site-packages\rest_framework\serializers.py", line 760, in data
    ret = super().data
  File "D:\Virtualenvs\wchat_shop\lib\site-packages\rest_framework\serializers.py", line 260, in data
    self._data = self.to_representation(self.instance)
  File "D:\Virtualenvs\wchat_shop\lib\site-packages\rest_framework\serializers.py", line 678, in to_representation
    self.child.to_representation(item) for item in iterable
  File "D:\Virtualenvs\wchat_shop\lib\site-packages\rest_framework\serializers.py", line 678, in <listcomp>
    self.child.to_representation(item) for item in iterable
  File "D:\Virtualenvs\wchat_shop\lib\site-packages\rest_framework\serializers.py", line 516, in to_representation
    attribute = field.get_attribute(instance)
  File "D:\Virtualenvs\wchat_shop\lib\site-packages\rest_framework\fields.py", line 454, in get_attribute
    return get_attribute(instance, self.source_attrs)
  File "D:\Virtualenvs\wchat_shop\lib\site-packages\rest_framework\fields.py", line 99, in get_attribute
    instance = instance()
  File "C:\Users\www97\Desktop\2020-01\server\api\models.py", line 45, in foods
    return FoodsModelSerializer(data=self.category.all(), many=True).data
  File "D:\Virtualenvs\wchat_shop\lib\site-packages\rest_framework\serializers.py", line 760, in data
    ret = super().data
  File "D:\Virtualenvs\wchat_shop\lib\site-packages\rest_framework\serializers.py", line 256, in data
    raise AssertionError(msg)
AssertionError: When a serializer is passed a `data` keyword argument you must call `.is_valid()` before attempting to access the serialized `.data` representation.
You should either call `.is_valid()` first, or access `.initial_data` instead.

During handling of the above exception, another exception occurred:

Traceback (most recent call last):
  File "D:\Virtualenvs\wchat_shop\lib\site-packages\rest_framework\settings.py", line 177, in import_from_string
    return import_string(val)
  File "D:\Virtualenvs\wchat_shop\lib\site-packages\django\utils\module_loading.py", line 17, in import_string
    module = import_module(module_path)
  File "D:\Virtualenvs\wchat_shop\lib\importlib\__init__.py", line 126, in import_module
    return _bootstrap._gcd_import(name[level:], package, level)
  File "<frozen importlib._bootstrap>", line 994, in _gcd_import
  File "<frozen importlib._bootstrap>", line 971, in _find_and_load
  File "<frozen importlib._bootstrap>", line 941, in _find_and_load_unlocked
  File "<frozen importlib._bootstrap>", line 219, in _call_with_frames_removed
  File "<frozen importlib._bootstrap>", line 994, in _gcd_import
  File "<frozen importlib._bootstrap>", line 971, in _find_and_load
  File "<frozen importlib._bootstrap>", line 953, in _find_and_load_unlocked
ModuleNotFoundError: No module named 'utils'

During handling of the above exception, another exception occurred:

Traceback (most recent call last):
  File "D:\Virtualenvs\wchat_shop\lib\site-packages\django\core\handlers\exception.py", line 35, in inner
    response = get_response(request)
  File "D:\Virtualenvs\wchat_shop\lib\site-packages\django\core\handlers\base.py", line 128, in _get_response
    response = self.process_exception_by_middleware(e, request)
  File "D:\Virtualenvs\wchat_shop\lib\site-packages\django\core\handlers\base.py", line 126, in _get_response
    response = wrapped_callback(request, *callback_args, **callback_kwargs)
  File "D:\Virtualenvs\wchat_shop\lib\site-packages\django\views\decorators\csrf.py", line 54, in wrapped_view
    return view_func(*args, **kwargs)
  File "D:\Virtualenvs\wchat_shop\lib\site-packages\django\views\generic\base.py", line 69, in view
    return self.dispatch(request, *args, **kwargs)
  File "D:\Virtualenvs\wchat_shop\lib\site-packages\rest_framework\views.py", line 505, in dispatch
    response = self.handle_exception(exc)
  File "D:\Virtualenvs\wchat_shop\lib\site-packages\rest_framework\views.py", line 459, in handle_exception
    exception_handler = self.get_exception_handler()
  File "D:\Virtualenvs\wchat_shop\lib\site-packages\rest_framework\views.py", line 298, in get_exception_handler
    return self.settings.EXCEPTION_HANDLER
  File "D:\Virtualenvs\wchat_shop\lib\site-packages\rest_framework\settings.py", line 220, in __getattr__
    val = perform_import(val, attr)
  File "D:\Virtualenvs\wchat_shop\lib\site-packages\rest_framework\settings.py", line 166, in perform_import
    return import_from_string(val, setting_name)
  File "D:\Virtualenvs\wchat_shop\lib\site-packages\rest_framework\settings.py", line 180, in import_from_string
    raise ImportError(msg)
ImportError: Could not import 'utils.exception.custom_exception_handler' for API setting 'EXCEPTION_HANDLER'. ModuleNotFoundError: No module named 'utils'.
ERROR 2020-01-06 17:59:12,658 basehttp 124 "GET /v1/food/show_food HTTP/1.1" 500 177567
ERROR 2020-01-06 18:00:47,061 exception 118 Internal Server Error: /v1/food/show_food
Traceback (most recent call last):
  File "D:\Virtualenvs\wchat_shop\lib\site-packages\rest_framework\views.py", line 502, in dispatch
    response = handler(request, *args, **kwargs)
  File "C:\Users\www97\Desktop\2020-01\server\api\views\store_view.py", line 23, in get
    data_list = CategoryModelSerializer(cat_data, many=True).data
  File "D:\Virtualenvs\wchat_shop\lib\site-packages\rest_framework\serializers.py", line 760, in data
    ret = super().data
  File "D:\Virtualenvs\wchat_shop\lib\site-packages\rest_framework\serializers.py", line 260, in data
    self._data = self.to_representation(self.instance)
  File "D:\Virtualenvs\wchat_shop\lib\site-packages\rest_framework\serializers.py", line 678, in to_representation
    self.child.to_representation(item) for item in iterable
  File "D:\Virtualenvs\wchat_shop\lib\site-packages\rest_framework\serializers.py", line 678, in <listcomp>
    self.child.to_representation(item) for item in iterable
  File "D:\Virtualenvs\wchat_shop\lib\site-packages\rest_framework\serializers.py", line 516, in to_representation
    attribute = field.get_attribute(instance)
  File "D:\Virtualenvs\wchat_shop\lib\site-packages\rest_framework\fields.py", line 454, in get_attribute
    return get_attribute(instance, self.source_attrs)
  File "D:\Virtualenvs\wchat_shop\lib\site-packages\rest_framework\fields.py", line 99, in get_attribute
    instance = instance()
  File "C:\Users\www97\Desktop\2020-01\server\api\models.py", line 45, in foods
    return FoodsModelSerializer(data=self.category.all(), many=True).data
  File "D:\Virtualenvs\wchat_shop\lib\site-packages\rest_framework\serializers.py", line 760, in data
    ret = super().data
  File "D:\Virtualenvs\wchat_shop\lib\site-packages\rest_framework\serializers.py", line 256, in data
    raise AssertionError(msg)
AssertionError: When a serializer is passed a `data` keyword argument you must call `.is_valid()` before attempting to access the serialized `.data` representation.
You should either call `.is_valid()` first, or access `.initial_data` instead.

During handling of the above exception, another exception occurred:

Traceback (most recent call last):
  File "D:\Virtualenvs\wchat_shop\lib\site-packages\rest_framework\settings.py", line 177, in import_from_string
    return import_string(val)
  File "D:\Virtualenvs\wchat_shop\lib\site-packages\django\utils\module_loading.py", line 17, in import_string
    module = import_module(module_path)
  File "D:\Virtualenvs\wchat_shop\lib\importlib\__init__.py", line 126, in import_module
    return _bootstrap._gcd_import(name[level:], package, level)
  File "<frozen importlib._bootstrap>", line 994, in _gcd_import
  File "<frozen importlib._bootstrap>", line 971, in _find_and_load
  File "<frozen importlib._bootstrap>", line 941, in _find_and_load_unlocked
  File "<frozen importlib._bootstrap>", line 219, in _call_with_frames_removed
  File "<frozen importlib._bootstrap>", line 994, in _gcd_import
  File "<frozen importlib._bootstrap>", line 971, in _find_and_load
  File "<frozen importlib._bootstrap>", line 953, in _find_and_load_unlocked
ModuleNotFoundError: No module named 'utils'

During handling of the above exception, another exception occurred:

Traceback (most recent call last):
  File "D:\Virtualenvs\wchat_shop\lib\site-packages\django\core\handlers\exception.py", line 35, in inner
    response = get_response(request)
  File "D:\Virtualenvs\wchat_shop\lib\site-packages\django\core\handlers\base.py", line 128, in _get_response
    response = self.process_exception_by_middleware(e, request)
  File "D:\Virtualenvs\wchat_shop\lib\site-packages\django\core\handlers\base.py", line 126, in _get_response
    response = wrapped_callback(request, *callback_args, **callback_kwargs)
  File "D:\Virtualenvs\wchat_shop\lib\site-packages\django\views\decorators\csrf.py", line 54, in wrapped_view
    return view_func(*args, **kwargs)
  File "D:\Virtualenvs\wchat_shop\lib\site-packages\django\views\generic\base.py", line 69, in view
    return self.dispatch(request, *args, **kwargs)
  File "D:\Virtualenvs\wchat_shop\lib\site-packages\rest_framework\views.py", line 505, in dispatch
    response = self.handle_exception(exc)
  File "D:\Virtualenvs\wchat_shop\lib\site-packages\rest_framework\views.py", line 459, in handle_exception
    exception_handler = self.get_exception_handler()
  File "D:\Virtualenvs\wchat_shop\lib\site-packages\rest_framework\views.py", line 298, in get_exception_handler
    return self.settings.EXCEPTION_HANDLER
  File "D:\Virtualenvs\wchat_shop\lib\site-packages\rest_framework\settings.py", line 220, in __getattr__
    val = perform_import(val, attr)
  File "D:\Virtualenvs\wchat_shop\lib\site-packages\rest_framework\settings.py", line 166, in perform_import
    return import_from_string(val, setting_name)
  File "D:\Virtualenvs\wchat_shop\lib\site-packages\rest_framework\settings.py", line 180, in import_from_string
    raise ImportError(msg)
ImportError: Could not import 'utils.exception.custom_exception_handler' for API setting 'EXCEPTION_HANDLER'. ModuleNotFoundError: No module named 'utils'.
ERROR 2020-01-06 18:00:47,149 basehttp 124 "GET /v1/food/show_food HTTP/1.1" 500 175672
ERROR 2020-01-06 18:01:46,247 exception 118 Internal Server Error: /v1/food/show_food
Traceback (most recent call last):
  File "D:\Virtualenvs\wchat_shop\lib\site-packages\rest_framework\views.py", line 502, in dispatch
    response = handler(request, *args, **kwargs)
  File "C:\Users\www97\Desktop\2020-01\server\api\views\store_view.py", line 23, in get
    data_list = CategoryModelSerializer(cat_data, many=True).data
  File "D:\Virtualenvs\wchat_shop\lib\site-packages\rest_framework\serializers.py", line 760, in data
    ret = super().data
  File "D:\Virtualenvs\wchat_shop\lib\site-packages\rest_framework\serializers.py", line 260, in data
    self._data = self.to_representation(self.instance)
  File "D:\Virtualenvs\wchat_shop\lib\site-packages\rest_framework\serializers.py", line 678, in to_representation
    self.child.to_representation(item) for item in iterable
  File "D:\Virtualenvs\wchat_shop\lib\site-packages\rest_framework\serializers.py", line 678, in <listcomp>
    self.child.to_representation(item) for item in iterable
  File "D:\Virtualenvs\wchat_shop\lib\site-packages\rest_framework\serializers.py", line 516, in to_representation
    attribute = field.get_attribute(instance)
  File "D:\Virtualenvs\wchat_shop\lib\site-packages\rest_framework\fields.py", line 454, in get_attribute
    return get_attribute(instance, self.source_attrs)
  File "D:\Virtualenvs\wchat_shop\lib\site-packages\rest_framework\fields.py", line 99, in get_attribute
    instance = instance()
  File "C:\Users\www97\Desktop\2020-01\server\api\models.py", line 45, in foods
    return FoodsModelSerializer(data=self.category.all(), many=True).data
  File "D:\Virtualenvs\wchat_shop\lib\site-packages\rest_framework\serializers.py", line 760, in data
    ret = super().data
  File "D:\Virtualenvs\wchat_shop\lib\site-packages\rest_framework\serializers.py", line 256, in data
    raise AssertionError(msg)
AssertionError: When a serializer is passed a `data` keyword argument you must call `.is_valid()` before attempting to access the serialized `.data` representation.
You should either call `.is_valid()` first, or access `.initial_data` instead.

During handling of the above exception, another exception occurred:

Traceback (most recent call last):
  File "D:\Virtualenvs\wchat_shop\lib\site-packages\rest_framework\settings.py", line 177, in import_from_string
    return import_string(val)
  File "D:\Virtualenvs\wchat_shop\lib\site-packages\django\utils\module_loading.py", line 17, in import_string
    module = import_module(module_path)
  File "D:\Virtualenvs\wchat_shop\lib\importlib\__init__.py", line 126, in import_module
    return _bootstrap._gcd_import(name[level:], package, level)
  File "<frozen importlib._bootstrap>", line 994, in _gcd_import
  File "<frozen importlib._bootstrap>", line 971, in _find_and_load
  File "<frozen importlib._bootstrap>", line 941, in _find_and_load_unlocked
  File "<frozen importlib._bootstrap>", line 219, in _call_with_frames_removed
  File "<frozen importlib._bootstrap>", line 994, in _gcd_import
  File "<frozen importlib._bootstrap>", line 971, in _find_and_load
  File "<frozen importlib._bootstrap>", line 953, in _find_and_load_unlocked
ModuleNotFoundError: No module named 'utils'

During handling of the above exception, another exception occurred:

Traceback (most recent call last):
  File "D:\Virtualenvs\wchat_shop\lib\site-packages\django\core\handlers\exception.py", line 35, in inner
    response = get_response(request)
  File "D:\Virtualenvs\wchat_shop\lib\site-packages\django\core\handlers\base.py", line 128, in _get_response
    response = self.process_exception_by_middleware(e, request)
  File "D:\Virtualenvs\wchat_shop\lib\site-packages\django\core\handlers\base.py", line 126, in _get_response
    response = wrapped_callback(request, *callback_args, **callback_kwargs)
  File "D:\Virtualenvs\wchat_shop\lib\site-packages\django\views\decorators\csrf.py", line 54, in wrapped_view
    return view_func(*args, **kwargs)
  File "D:\Virtualenvs\wchat_shop\lib\site-packages\django\views\generic\base.py", line 69, in view
    return self.dispatch(request, *args, **kwargs)
  File "D:\Virtualenvs\wchat_shop\lib\site-packages\rest_framework\views.py", line 505, in dispatch
    response = self.handle_exception(exc)
  File "D:\Virtualenvs\wchat_shop\lib\site-packages\rest_framework\views.py", line 459, in handle_exception
    exception_handler = self.get_exception_handler()
  File "D:\Virtualenvs\wchat_shop\lib\site-packages\rest_framework\views.py", line 298, in get_exception_handler
    return self.settings.EXCEPTION_HANDLER
  File "D:\Virtualenvs\wchat_shop\lib\site-packages\rest_framework\settings.py", line 220, in __getattr__
    val = perform_import(val, attr)
  File "D:\Virtualenvs\wchat_shop\lib\site-packages\rest_framework\settings.py", line 166, in perform_import
    return import_from_string(val, setting_name)
  File "D:\Virtualenvs\wchat_shop\lib\site-packages\rest_framework\settings.py", line 180, in import_from_string
    raise ImportError(msg)
ImportError: Could not import 'utils.exception.exception_handler' for API setting 'EXCEPTION_HANDLER'. ModuleNotFoundError: No module named 'utils'.
ERROR 2020-01-06 18:01:46,343 basehttp 124 "GET /v1/food/show_food HTTP/1.1" 500 175581
INFO 2020-01-06 18:05:49,471 basehttp 124 "GET /v1/food/show_food HTTP/1.1" 200 537
INFO 2020-01-06 18:09:27,019 basehttp 124 "GET /v1/food/show_food HTTP/1.1" 200 537
INFO 2020-01-06 18:09:37,867 basehttp 124 "GET /v1/food/show_food HTTP/1.1" 200 537
INFO 2020-01-06 18:11:45,899 basehttp 124 "GET /v1/food/show_food HTTP/1.1" 200 537
ERROR 2020-01-06 19:03:03,339 exception 118 Internal Server Error: /v1/food/show_food
Traceback (most recent call last):
  File "D:\Virtualenvs\wchat_shop\lib\site-packages\rest_framework\views.py", line 502, in dispatch
    response = handler(request, *args, **kwargs)
  File "C:\Users\www97\Desktop\2020-01\server\api\views\store_view.py", line 22, in get
    data_list = CategoryModelSerializer(instance=cat_data, many=True, context={'request': request}).data
  File "D:\Virtualenvs\wchat_shop\lib\site-packages\rest_framework\serializers.py", line 760, in data
    ret = super().data
  File "D:\Virtualenvs\wchat_shop\lib\site-packages\rest_framework\serializers.py", line 260, in data
    self._data = self.to_representation(self.instance)
  File "D:\Virtualenvs\wchat_shop\lib\site-packages\rest_framework\serializers.py", line 678, in to_representation
    self.child.to_representation(item) for item in iterable
  File "D:\Virtualenvs\wchat_shop\lib\site-packages\rest_framework\serializers.py", line 678, in <listcomp>
    self.child.to_representation(item) for item in iterable
  File "D:\Virtualenvs\wchat_shop\lib\site-packages\rest_framework\serializers.py", line 514, in to_representation
    for field in fields:
  File "D:\Virtualenvs\wchat_shop\lib\site-packages\rest_framework\serializers.py", line 375, in _readable_fields
    for field in self.fields.values():
  File "D:\Virtualenvs\wchat_shop\lib\site-packages\django\utils\functional.py", line 36, in __get__
    res = instance.__dict__[self.name] = self.func(instance)
  File "D:\Virtualenvs\wchat_shop\lib\site-packages\rest_framework\serializers.py", line 363, in fields
    for key, value in self.get_fields().items():
  File "D:\Virtualenvs\wchat_shop\lib\site-packages\rest_framework\serializers.py", line 1063, in get_fields
    source, info, model, depth
  File "D:\Virtualenvs\wchat_shop\lib\site-packages\rest_framework\serializers.py", line 1208, in build_field
    return self.build_unknown_field(field_name, model_class)
  File "D:\Virtualenvs\wchat_shop\lib\site-packages\rest_framework\serializers.py", line 1325, in build_unknown_field
    (field_name, model_class.__name__)
django.core.exceptions.ImproperlyConfigured: Field name `foodsid` is not valid for model `Category`.

During handling of the above exception, another exception occurred:

Traceback (most recent call last):
  File "D:\Virtualenvs\wchat_shop\lib\site-packages\rest_framework\settings.py", line 177, in import_from_string
    return import_string(val)
  File "D:\Virtualenvs\wchat_shop\lib\site-packages\django\utils\module_loading.py", line 17, in import_string
    module = import_module(module_path)
  File "D:\Virtualenvs\wchat_shop\lib\importlib\__init__.py", line 126, in import_module
    return _bootstrap._gcd_import(name[level:], package, level)
  File "<frozen importlib._bootstrap>", line 994, in _gcd_import
  File "<frozen importlib._bootstrap>", line 971, in _find_and_load
  File "<frozen importlib._bootstrap>", line 941, in _find_and_load_unlocked
  File "<frozen importlib._bootstrap>", line 219, in _call_with_frames_removed
  File "<frozen importlib._bootstrap>", line 994, in _gcd_import
  File "<frozen importlib._bootstrap>", line 971, in _find_and_load
  File "<frozen importlib._bootstrap>", line 953, in _find_and_load_unlocked
ModuleNotFoundError: No module named 'utils'

During handling of the above exception, another exception occurred:

Traceback (most recent call last):
  File "D:\Virtualenvs\wchat_shop\lib\site-packages\django\core\handlers\exception.py", line 35, in inner
    response = get_response(request)
  File "D:\Virtualenvs\wchat_shop\lib\site-packages\django\core\handlers\base.py", line 128, in _get_response
    response = self.process_exception_by_middleware(e, request)
  File "D:\Virtualenvs\wchat_shop\lib\site-packages\django\core\handlers\base.py", line 126, in _get_response
    response = wrapped_callback(request, *callback_args, **callback_kwargs)
  File "D:\Virtualenvs\wchat_shop\lib\site-packages\django\views\decorators\csrf.py", line 54, in wrapped_view
    return view_func(*args, **kwargs)
  File "D:\Virtualenvs\wchat_shop\lib\site-packages\django\views\generic\base.py", line 69, in view
    return self.dispatch(request, *args, **kwargs)
  File "D:\Virtualenvs\wchat_shop\lib\site-packages\rest_framework\views.py", line 505, in dispatch
    response = self.handle_exception(exc)
  File "D:\Virtualenvs\wchat_shop\lib\site-packages\rest_framework\views.py", line 459, in handle_exception
    exception_handler = self.get_exception_handler()
  File "D:\Virtualenvs\wchat_shop\lib\site-packages\rest_framework\views.py", line 298, in get_exception_handler
    return self.settings.EXCEPTION_HANDLER
  File "D:\Virtualenvs\wchat_shop\lib\site-packages\rest_framework\settings.py", line 220, in __getattr__
    val = perform_import(val, attr)
  File "D:\Virtualenvs\wchat_shop\lib\site-packages\rest_framework\settings.py", line 166, in perform_import
    return import_from_string(val, setting_name)
  File "D:\Virtualenvs\wchat_shop\lib\site-packages\rest_framework\settings.py", line 180, in import_from_string
    raise ImportError(msg)
ImportError: Could not import 'utils.exception.exception_handler' for API setting 'EXCEPTION_HANDLER'. ModuleNotFoundError: No module named 'utils'.
ERROR 2020-01-06 19:03:03,423 basehttp 124 "GET /v1/food/show_food HTTP/1.1" 500 181641
ERROR 2020-01-06 19:03:14,913 exception 118 Internal Server Error: /v1/food/show_food
Traceback (most recent call last):
  File "D:\Virtualenvs\wchat_shop\lib\site-packages\rest_framework\views.py", line 502, in dispatch
    response = handler(request, *args, **kwargs)
  File "C:\Users\www97\Desktop\2020-01\server\api\views\store_view.py", line 22, in get
    data_list = CategoryModelSerializer(instance=cat_data, many=True, context={'request': request}).data
  File "D:\Virtualenvs\wchat_shop\lib\site-packages\rest_framework\serializers.py", line 760, in data
    ret = super().data
  File "D:\Virtualenvs\wchat_shop\lib\site-packages\rest_framework\serializers.py", line 260, in data
    self._data = self.to_representation(self.instance)
  File "D:\Virtualenvs\wchat_shop\lib\site-packages\rest_framework\serializers.py", line 678, in to_representation
    self.child.to_representation(item) for item in iterable
  File "D:\Virtualenvs\wchat_shop\lib\site-packages\rest_framework\serializers.py", line 678, in <listcomp>
    self.child.to_representation(item) for item in iterable
  File "D:\Virtualenvs\wchat_shop\lib\site-packages\rest_framework\serializers.py", line 514, in to_representation
    for field in fields:
  File "D:\Virtualenvs\wchat_shop\lib\site-packages\rest_framework\serializers.py", line 375, in _readable_fields
    for field in self.fields.values():
  File "D:\Virtualenvs\wchat_shop\lib\site-packages\django\utils\functional.py", line 36, in __get__
    res = instance.__dict__[self.name] = self.func(instance)
  File "D:\Virtualenvs\wchat_shop\lib\site-packages\rest_framework\serializers.py", line 363, in fields
    for key, value in self.get_fields().items():
  File "D:\Virtualenvs\wchat_shop\lib\site-packages\rest_framework\serializers.py", line 1063, in get_fields
    source, info, model, depth
  File "D:\Virtualenvs\wchat_shop\lib\site-packages\rest_framework\serializers.py", line 1208, in build_field
    return self.build_unknown_field(field_name, model_class)
  File "D:\Virtualenvs\wchat_shop\lib\site-packages\rest_framework\serializers.py", line 1325, in build_unknown_field
    (field_name, model_class.__name__)
django.core.exceptions.ImproperlyConfigured: Field name `foodsid` is not valid for model `Category`.

During handling of the above exception, another exception occurred:

Traceback (most recent call last):
  File "D:\Virtualenvs\wchat_shop\lib\site-packages\rest_framework\settings.py", line 177, in import_from_string
    return import_string(val)
  File "D:\Virtualenvs\wchat_shop\lib\site-packages\django\utils\module_loading.py", line 17, in import_string
    module = import_module(module_path)
  File "D:\Virtualenvs\wchat_shop\lib\importlib\__init__.py", line 126, in import_module
    return _bootstrap._gcd_import(name[level:], package, level)
  File "<frozen importlib._bootstrap>", line 994, in _gcd_import
  File "<frozen importlib._bootstrap>", line 971, in _find_and_load
  File "<frozen importlib._bootstrap>", line 941, in _find_and_load_unlocked
  File "<frozen importlib._bootstrap>", line 219, in _call_with_frames_removed
  File "<frozen importlib._bootstrap>", line 994, in _gcd_import
  File "<frozen importlib._bootstrap>", line 971, in _find_and_load
  File "<frozen importlib._bootstrap>", line 953, in _find_and_load_unlocked
ModuleNotFoundError: No module named 'utils'

During handling of the above exception, another exception occurred:

Traceback (most recent call last):
  File "D:\Virtualenvs\wchat_shop\lib\site-packages\django\core\handlers\exception.py", line 35, in inner
    response = get_response(request)
  File "D:\Virtualenvs\wchat_shop\lib\site-packages\django\core\handlers\base.py", line 128, in _get_response
    response = self.process_exception_by_middleware(e, request)
  File "D:\Virtualenvs\wchat_shop\lib\site-packages\django\core\handlers\base.py", line 126, in _get_response
    response = wrapped_callback(request, *callback_args, **callback_kwargs)
  File "D:\Virtualenvs\wchat_shop\lib\site-packages\django\views\decorators\csrf.py", line 54, in wrapped_view
    return view_func(*args, **kwargs)
  File "D:\Virtualenvs\wchat_shop\lib\site-packages\django\views\generic\base.py", line 69, in view
    return self.dispatch(request, *args, **kwargs)
  File "D:\Virtualenvs\wchat_shop\lib\site-packages\rest_framework\views.py", line 505, in dispatch
    response = self.handle_exception(exc)
  File "D:\Virtualenvs\wchat_shop\lib\site-packages\rest_framework\views.py", line 459, in handle_exception
    exception_handler = self.get_exception_handler()
  File "D:\Virtualenvs\wchat_shop\lib\site-packages\rest_framework\views.py", line 298, in get_exception_handler
    return self.settings.EXCEPTION_HANDLER
  File "D:\Virtualenvs\wchat_shop\lib\site-packages\rest_framework\settings.py", line 220, in __getattr__
    val = perform_import(val, attr)
  File "D:\Virtualenvs\wchat_shop\lib\site-packages\rest_framework\settings.py", line 166, in perform_import
    return import_from_string(val, setting_name)
  File "D:\Virtualenvs\wchat_shop\lib\site-packages\rest_framework\settings.py", line 180, in import_from_string
    raise ImportError(msg)
ImportError: Could not import 'utils.exception.exception_handler' for API setting 'EXCEPTION_HANDLER'. ModuleNotFoundError: No module named 'utils'.
ERROR 2020-01-06 19:03:15,003 basehttp 124 "GET /v1/food/show_food HTTP/1.1" 500 181641
INFO 2020-01-06 19:04:07,271 basehttp 124 "GET /v1/food/show_food HTTP/1.1" 200 565
INFO 2020-01-06 19:11:49,140 basehttp 124 "POST /v1/food/show_detail HTTP/1.1" 200 4
INFO 2020-01-06 19:12:50,009 basehttp 124 "POST /v1/food/show_detail HTTP/1.1" 200 4
INFO 2020-01-06 19:13:50,894 basehttp 124 "POST /v1/food/show_detail HTTP/1.1" 200 4
ERROR 2020-01-06 19:14:05,433 exception 118 Internal Server Error: /v1/food/static/img/Yellow_pheasant.jpg
Traceback (most recent call last):
  File "D:\Virtualenvs\wchat_shop\lib\site-packages\django\core\handlers\exception.py", line 35, in inner
    response = get_response(request)
  File "D:\Virtualenvs\wchat_shop\lib\site-packages\django\core\handlers\base.py", line 128, in _get_response
    response = self.process_exception_by_middleware(e, request)
  File "D:\Virtualenvs\wchat_shop\lib\site-packages\django\core\handlers\base.py", line 126, in _get_response
    response = wrapped_callback(request, *callback_args, **callback_kwargs)
TypeError: serve() got an unexpected keyword argument 'PATH'
ERROR 2020-01-06 19:14:05,664 basehttp 124 "GET /v1/food/static/img/Yellow_pheasant.jpg HTTP/1.1" 500 71412
ERROR 2020-01-06 19:24:05,725 exception 118 Internal Server Error: /v1/food/show_detail
Traceback (most recent call last):
  File "D:\Virtualenvs\wchat_shop\lib\site-packages\rest_framework\views.py", line 502, in dispatch
    response = handler(request, *args, **kwargs)
  File "C:\Users\www97\Desktop\2020-01\server\api\views\store_view.py", line 30, in post
    food_ser = FoodsModelSerializer(instance=food_obj).data
  File "D:\Virtualenvs\wchat_shop\lib\site-packages\rest_framework\serializers.py", line 562, in data
    ret = super().data
  File "D:\Virtualenvs\wchat_shop\lib\site-packages\rest_framework\serializers.py", line 260, in data
    self._data = self.to_representation(self.instance)
  File "D:\Virtualenvs\wchat_shop\lib\site-packages\rest_framework\serializers.py", line 516, in to_representation
    attribute = field.get_attribute(instance)
  File "D:\Virtualenvs\wchat_shop\lib\site-packages\rest_framework\fields.py", line 454, in get_attribute
    return get_attribute(instance, self.source_attrs)
  File "D:\Virtualenvs\wchat_shop\lib\site-packages\rest_framework\fields.py", line 94, in get_attribute
    instance = getattr(instance, attr)
  File "C:\Users\www97\Desktop\2020-01\server\api\models.py", line 27, in FoodDetails
    detail_obj = FoodDetail.objects.filter(food_detail=self.detail).frist()
  File "D:\Virtualenvs\wchat_shop\lib\site-packages\django\db\models\manager.py", line 82, in manager_method
    return getattr(self.get_queryset(), name)(*args, **kwargs)
  File "D:\Virtualenvs\wchat_shop\lib\site-packages\django\db\models\query.py", line 836, in filter
    return self._filter_or_exclude(False, *args, **kwargs)
  File "D:\Virtualenvs\wchat_shop\lib\site-packages\django\db\models\query.py", line 854, in _filter_or_exclude
    clone.query.add_q(Q(*args, **kwargs))
  File "D:\Virtualenvs\wchat_shop\lib\site-packages\django\db\models\sql\query.py", line 1253, in add_q
    clause, _ = self._add_q(q_object, self.used_aliases)
  File "D:\Virtualenvs\wchat_shop\lib\site-packages\django\db\models\sql\query.py", line 1277, in _add_q
    split_subq=split_subq,
  File "D:\Virtualenvs\wchat_shop\lib\site-packages\django\db\models\sql\query.py", line 1187, in build_filter
    self.check_related_objects(join_info.final_field, value, join_info.opts)
  File "D:\Virtualenvs\wchat_shop\lib\site-packages\django\db\models\sql\query.py", line 1050, in check_related_objects
    self.check_query_object_type(value, opts, field)
  File "D:\Virtualenvs\wchat_shop\lib\site-packages\django\db\models\sql\query.py", line 1033, in check_query_object_type
    (value, opts.object_name))
ValueError: Cannot query "菜品详情": Must be "Food" instance.

During handling of the above exception, another exception occurred:

Traceback (most recent call last):
  File "D:\Virtualenvs\wchat_shop\lib\site-packages\rest_framework\settings.py", line 177, in import_from_string
    return import_string(val)
  File "D:\Virtualenvs\wchat_shop\lib\site-packages\django\utils\module_loading.py", line 17, in import_string
    module = import_module(module_path)
  File "D:\Virtualenvs\wchat_shop\lib\importlib\__init__.py", line 126, in import_module
    return _bootstrap._gcd_import(name[level:], package, level)
  File "<frozen importlib._bootstrap>", line 994, in _gcd_import
  File "<frozen importlib._bootstrap>", line 971, in _find_and_load
  File "<frozen importlib._bootstrap>", line 941, in _find_and_load_unlocked
  File "<frozen importlib._bootstrap>", line 219, in _call_with_frames_removed
  File "<frozen importlib._bootstrap>", line 994, in _gcd_import
  File "<frozen importlib._bootstrap>", line 971, in _find_and_load
  File "<frozen importlib._bootstrap>", line 953, in _find_and_load_unlocked
ModuleNotFoundError: No module named 'utils'

During handling of the above exception, another exception occurred:

Traceback (most recent call last):
  File "D:\Virtualenvs\wchat_shop\lib\site-packages\django\core\handlers\exception.py", line 35, in inner
    response = get_response(request)
  File "D:\Virtualenvs\wchat_shop\lib\site-packages\django\core\handlers\base.py", line 128, in _get_response
    response = self.process_exception_by_middleware(e, request)
  File "D:\Virtualenvs\wchat_shop\lib\site-packages\django\core\handlers\base.py", line 126, in _get_response
    response = wrapped_callback(request, *callback_args, **callback_kwargs)
  File "D:\Virtualenvs\wchat_shop\lib\site-packages\django\views\decorators\csrf.py", line 54, in wrapped_view
    return view_func(*args, **kwargs)
  File "D:\Virtualenvs\wchat_shop\lib\site-packages\django\views\generic\base.py", line 69, in view
    return self.dispatch(request, *args, **kwargs)
  File "D:\Virtualenvs\wchat_shop\lib\site-packages\rest_framework\views.py", line 505, in dispatch
    response = self.handle_exception(exc)
  File "D:\Virtualenvs\wchat_shop\lib\site-packages\rest_framework\views.py", line 459, in handle_exception
    exception_handler = self.get_exception_handler()
  File "D:\Virtualenvs\wchat_shop\lib\site-packages\rest_framework\views.py", line 298, in get_exception_handler
    return self.settings.EXCEPTION_HANDLER
  File "D:\Virtualenvs\wchat_shop\lib\site-packages\rest_framework\settings.py", line 220, in __getattr__
    val = perform_import(val, attr)
  File "D:\Virtualenvs\wchat_shop\lib\site-packages\rest_framework\settings.py", line 166, in perform_import
    return import_from_string(val, setting_name)
  File "D:\Virtualenvs\wchat_shop\lib\site-packages\rest_framework\settings.py", line 180, in import_from_string
    raise ImportError(msg)
ImportError: Could not import 'utils.exception.exception_handler' for API setting 'EXCEPTION_HANDLER'. ModuleNotFoundError: No module named 'utils'.
ERROR 2020-01-06 19:24:05,962 basehttp 124 "POST /v1/food/show_detail HTTP/1.1" 500 200454
ERROR 2020-01-06 19:27:40,636 exception 118 Internal Server Error: /v1/food/show_detail
Traceback (most recent call last):
  File "D:\Virtualenvs\wchat_shop\lib\site-packages\rest_framework\views.py", line 502, in dispatch
    response = handler(request, *args, **kwargs)
  File "C:\Users\www97\Desktop\2020-01\server\api\views\store_view.py", line 30, in post
    food_ser = FoodsModelSerializer(instance=food_obj).data
  File "D:\Virtualenvs\wchat_shop\lib\site-packages\rest_framework\serializers.py", line 562, in data
    ret = super().data
  File "D:\Virtualenvs\wchat_shop\lib\site-packages\rest_framework\serializers.py", line 260, in data
    self._data = self.to_representation(self.instance)
  File "D:\Virtualenvs\wchat_shop\lib\site-packages\rest_framework\serializers.py", line 516, in to_representation
    attribute = field.get_attribute(instance)
  File "D:\Virtualenvs\wchat_shop\lib\site-packages\rest_framework\fields.py", line 454, in get_attribute
    return get_attribute(instance, self.source_attrs)
  File "D:\Virtualenvs\wchat_shop\lib\site-packages\rest_framework\fields.py", line 94, in get_attribute
    instance = getattr(instance, attr)
  File "C:\Users\www97\Desktop\2020-01\server\api\models.py", line 27, in FoodDetails
    detail_obj = FoodDetail.objects.filter(PK=self.detail).frist()
  File "D:\Virtualenvs\wchat_shop\lib\site-packages\django\db\models\manager.py", line 82, in manager_method
    return getattr(self.get_queryset(), name)(*args, **kwargs)
  File "D:\Virtualenvs\wchat_shop\lib\site-packages\django\db\models\query.py", line 836, in filter
    return self._filter_or_exclude(False, *args, **kwargs)
  File "D:\Virtualenvs\wchat_shop\lib\site-packages\django\db\models\query.py", line 854, in _filter_or_exclude
    clone.query.add_q(Q(*args, **kwargs))
  File "D:\Virtualenvs\wchat_shop\lib\site-packages\django\db\models\sql\query.py", line 1253, in add_q
    clause, _ = self._add_q(q_object, self.used_aliases)
  File "D:\Virtualenvs\wchat_shop\lib\site-packages\django\db\models\sql\query.py", line 1277, in _add_q
    split_subq=split_subq,
  File "D:\Virtualenvs\wchat_shop\lib\site-packages\django\db\models\sql\query.py", line 1153, in build_filter
    lookups, parts, reffed_expression = self.solve_lookup_type(arg)
  File "D:\Virtualenvs\wchat_shop\lib\site-packages\django\db\models\sql\query.py", line 1015, in solve_lookup_type
    _, field, _, lookup_parts = self.names_to_path(lookup_splitted, self.get_meta())
  File "D:\Virtualenvs\wchat_shop\lib\site-packages\django\db\models\sql\query.py", line 1379, in names_to_path
    "Choices are: %s" % (name, ", ".join(available)))
django.core.exceptions.FieldError: Cannot resolve keyword 'PK' into field. Choices are: create, dec, food_detail, id, ingredient, is_delete, is_show, sale_num

During handling of the above exception, another exception occurred:

Traceback (most recent call last):
  File "D:\Virtualenvs\wchat_shop\lib\site-packages\rest_framework\settings.py", line 177, in import_from_string
    return import_string(val)
  File "D:\Virtualenvs\wchat_shop\lib\site-packages\django\utils\module_loading.py", line 17, in import_string
    module = import_module(module_path)
  File "D:\Virtualenvs\wchat_shop\lib\importlib\__init__.py", line 126, in import_module
    return _bootstrap._gcd_import(name[level:], package, level)
  File "<frozen importlib._bootstrap>", line 994, in _gcd_import
  File "<frozen importlib._bootstrap>", line 971, in _find_and_load
  File "<frozen importlib._bootstrap>", line 941, in _find_and_load_unlocked
  File "<frozen importlib._bootstrap>", line 219, in _call_with_frames_removed
  File "<frozen importlib._bootstrap>", line 994, in _gcd_import
  File "<frozen importlib._bootstrap>", line 971, in _find_and_load
  File "<frozen importlib._bootstrap>", line 953, in _find_and_load_unlocked
ModuleNotFoundError: No module named 'utils'

During handling of the above exception, another exception occurred:

Traceback (most recent call last):
  File "D:\Virtualenvs\wchat_shop\lib\site-packages\django\core\handlers\exception.py", line 35, in inner
    response = get_response(request)
  File "D:\Virtualenvs\wchat_shop\lib\site-packages\django\core\handlers\base.py", line 128, in _get_response
    response = self.process_exception_by_middleware(e, request)
  File "D:\Virtualenvs\wchat_shop\lib\site-packages\django\core\handlers\base.py", line 126, in _get_response
    response = wrapped_callback(request, *callback_args, **callback_kwargs)
  File "D:\Virtualenvs\wchat_shop\lib\site-packages\django\views\decorators\csrf.py", line 54, in wrapped_view
    return view_func(*args, **kwargs)
  File "D:\Virtualenvs\wchat_shop\lib\site-packages\django\views\generic\base.py", line 69, in view
    return self.dispatch(request, *args, **kwargs)
  File "D:\Virtualenvs\wchat_shop\lib\site-packages\rest_framework\views.py", line 505, in dispatch
    response = self.handle_exception(exc)
  File "D:\Virtualenvs\wchat_shop\lib\site-packages\rest_framework\views.py", line 459, in handle_exception
    exception_handler = self.get_exception_handler()
  File "D:\Virtualenvs\wchat_shop\lib\site-packages\rest_framework\views.py", line 298, in get_exception_handler
    return self.settings.EXCEPTION_HANDLER
  File "D:\Virtualenvs\wchat_shop\lib\site-packages\rest_framework\settings.py", line 220, in __getattr__
    val = perform_import(val, attr)
  File "D:\Virtualenvs\wchat_shop\lib\site-packages\rest_framework\settings.py", line 166, in perform_import
    return import_from_string(val, setting_name)
  File "D:\Virtualenvs\wchat_shop\lib\site-packages\rest_framework\settings.py", line 180, in import_from_string
    raise ImportError(msg)
ImportError: Could not import 'utils.exception.exception_handler' for API setting 'EXCEPTION_HANDLER'. ModuleNotFoundError: No module named 'utils'.
ERROR 2020-01-06 19:27:40,877 basehttp 124 "POST /v1/food/show_detail HTTP/1.1" 500 200196
ERROR 2020-01-06 19:32:57,055 exception 118 Internal Server Error: /v1/food/show_detail
Traceback (most recent call last):
  File "D:\Virtualenvs\wchat_shop\lib\site-packages\rest_framework\views.py", line 502, in dispatch
    response = handler(request, *args, **kwargs)
  File "C:\Users\www97\Desktop\2020-01\server\api\views\store_view.py", line 30, in post
    food_ser = FoodsModelSerializer(instance=food_obj).data
  File "D:\Virtualenvs\wchat_shop\lib\site-packages\rest_framework\serializers.py", line 562, in data
    ret = super().data
  File "D:\Virtualenvs\wchat_shop\lib\site-packages\rest_framework\serializers.py", line 260, in data
    self._data = self.to_representation(self.instance)
  File "D:\Virtualenvs\wchat_shop\lib\site-packages\rest_framework\serializers.py", line 516, in to_representation
    attribute = field.get_attribute(instance)
  File "D:\Virtualenvs\wchat_shop\lib\site-packages\rest_framework\fields.py", line 454, in get_attribute
    return get_attribute(instance, self.source_attrs)
  File "D:\Virtualenvs\wchat_shop\lib\site-packages\rest_framework\fields.py", line 94, in get_attribute
    instance = getattr(instance, attr)
  File "C:\Users\www97\Desktop\2020-01\server\api\models.py", line 29, in FoodDetails
    return FoodDetailModelSerializer(instance=detail_obj).data
  File "D:\Virtualenvs\wchat_shop\lib\site-packages\rest_framework\serializers.py", line 562, in data
    ret = super().data
  File "D:\Virtualenvs\wchat_shop\lib\site-packages\rest_framework\serializers.py", line 260, in data
    self._data = self.to_representation(self.instance)
  File "D:\Virtualenvs\wchat_shop\lib\site-packages\rest_framework\serializers.py", line 514, in to_representation
    for field in fields:
  File "D:\Virtualenvs\wchat_shop\lib\site-packages\rest_framework\serializers.py", line 375, in _readable_fields
    for field in self.fields.values():
  File "D:\Virtualenvs\wchat_shop\lib\site-packages\django\utils\functional.py", line 36, in __get__
    res = instance.__dict__[self.name] = self.func(instance)
  File "D:\Virtualenvs\wchat_shop\lib\site-packages\rest_framework\serializers.py", line 363, in fields
    for key, value in self.get_fields().items():
  File "D:\Virtualenvs\wchat_shop\lib\site-packages\rest_framework\serializers.py", line 1063, in get_fields
    source, info, model, depth
  File "D:\Virtualenvs\wchat_shop\lib\site-packages\rest_framework\serializers.py", line 1208, in build_field
    return self.build_unknown_field(field_name, model_class)
  File "D:\Virtualenvs\wchat_shop\lib\site-packages\rest_framework\serializers.py", line 1325, in build_unknown_field
    (field_name, model_class.__name__)
django.core.exceptions.ImproperlyConfigured: Field name `img` is not valid for model `FoodDetail`.

During handling of the above exception, another exception occurred:

Traceback (most recent call last):
  File "D:\Virtualenvs\wchat_shop\lib\site-packages\rest_framework\settings.py", line 177, in import_from_string
    return import_string(val)
  File "D:\Virtualenvs\wchat_shop\lib\site-packages\django\utils\module_loading.py", line 17, in import_string
    module = import_module(module_path)
  File "D:\Virtualenvs\wchat_shop\lib\importlib\__init__.py", line 126, in import_module
    return _bootstrap._gcd_import(name[level:], package, level)
  File "<frozen importlib._bootstrap>", line 994, in _gcd_import
  File "<frozen importlib._bootstrap>", line 971, in _find_and_load
  File "<frozen importlib._bootstrap>", line 941, in _find_and_load_unlocked
  File "<frozen importlib._bootstrap>", line 219, in _call_with_frames_removed
  File "<frozen importlib._bootstrap>", line 994, in _gcd_import
  File "<frozen importlib._bootstrap>", line 971, in _find_and_load
  File "<frozen importlib._bootstrap>", line 953, in _find_and_load_unlocked
ModuleNotFoundError: No module named 'utils'

During handling of the above exception, another exception occurred:

Traceback (most recent call last):
  File "D:\Virtualenvs\wchat_shop\lib\site-packages\django\core\handlers\exception.py", line 35, in inner
    response = get_response(request)
  File "D:\Virtualenvs\wchat_shop\lib\site-packages\django\core\handlers\base.py", line 128, in _get_response
    response = self.process_exception_by_middleware(e, request)
  File "D:\Virtualenvs\wchat_shop\lib\site-packages\django\core\handlers\base.py", line 126, in _get_response
    response = wrapped_callback(request, *callback_args, **callback_kwargs)
  File "D:\Virtualenvs\wchat_shop\lib\site-packages\django\views\decorators\csrf.py", line 54, in wrapped_view
    return view_func(*args, **kwargs)
  File "D:\Virtualenvs\wchat_shop\lib\site-packages\django\views\generic\base.py", line 69, in view
    return self.dispatch(request, *args, **kwargs)
  File "D:\Virtualenvs\wchat_shop\lib\site-packages\rest_framework\views.py", line 505, in dispatch
    response = self.handle_exception(exc)
  File "D:\Virtualenvs\wchat_shop\lib\site-packages\rest_framework\views.py", line 459, in handle_exception
    exception_handler = self.get_exception_handler()
  File "D:\Virtualenvs\wchat_shop\lib\site-packages\rest_framework\views.py", line 298, in get_exception_handler
    return self.settings.EXCEPTION_HANDLER
  File "D:\Virtualenvs\wchat_shop\lib\site-packages\rest_framework\settings.py", line 220, in __getattr__
    val = perform_import(val, attr)
  File "D:\Virtualenvs\wchat_shop\lib\site-packages\rest_framework\settings.py", line 166, in perform_import
    return import_from_string(val, setting_name)
  File "D:\Virtualenvs\wchat_shop\lib\site-packages\rest_framework\settings.py", line 180, in import_from_string
    raise ImportError(msg)
ImportError: Could not import 'utils.exception.exception_handler' for API setting 'EXCEPTION_HANDLER'. ModuleNotFoundError: No module named 'utils'.
ERROR 2020-01-06 19:32:57,288 basehttp 124 "POST /v1/food/show_detail HTTP/1.1" 500 202394
ERROR 2020-01-06 19:45:51,801 exception 118 Internal Server Error: /v1/food/show_detail
Traceback (most recent call last):
  File "D:\Virtualenvs\wchat_shop\lib\site-packages\rest_framework\views.py", line 502, in dispatch
    response = handler(request, *args, **kwargs)
  File "C:\Users\www97\Desktop\2020-01\server\api\views\store_view.py", line 31, in post
    food_detail_obj = FoodDetail.objects.filter(pk=food_obj.detail_id).frist()
AttributeError: 'QuerySet' object has no attribute 'frist'

During handling of the above exception, another exception occurred:

Traceback (most recent call last):
  File "D:\Virtualenvs\wchat_shop\lib\site-packages\rest_framework\settings.py", line 177, in import_from_string
    return import_string(val)
  File "D:\Virtualenvs\wchat_shop\lib\site-packages\django\utils\module_loading.py", line 17, in import_string
    module = import_module(module_path)
  File "D:\Virtualenvs\wchat_shop\lib\importlib\__init__.py", line 126, in import_module
    return _bootstrap._gcd_import(name[level:], package, level)
  File "<frozen importlib._bootstrap>", line 994, in _gcd_import
  File "<frozen importlib._bootstrap>", line 971, in _find_and_load
  File "<frozen importlib._bootstrap>", line 941, in _find_and_load_unlocked
  File "<frozen importlib._bootstrap>", line 219, in _call_with_frames_removed
  File "<frozen importlib._bootstrap>", line 994, in _gcd_import
  File "<frozen importlib._bootstrap>", line 971, in _find_and_load
  File "<frozen importlib._bootstrap>", line 953, in _find_and_load_unlocked
ModuleNotFoundError: No module named 'utils'

During handling of the above exception, another exception occurred:

Traceback (most recent call last):
  File "D:\Virtualenvs\wchat_shop\lib\site-packages\django\core\handlers\exception.py", line 35, in inner
    response = get_response(request)
  File "D:\Virtualenvs\wchat_shop\lib\site-packages\django\core\handlers\base.py", line 128, in _get_response
    response = self.process_exception_by_middleware(e, request)
  File "D:\Virtualenvs\wchat_shop\lib\site-packages\django\core\handlers\base.py", line 126, in _get_response
    response = wrapped_callback(request, *callback_args, **callback_kwargs)
  File "D:\Virtualenvs\wchat_shop\lib\site-packages\django\views\decorators\csrf.py", line 54, in wrapped_view
    return view_func(*args, **kwargs)
  File "D:\Virtualenvs\wchat_shop\lib\site-packages\django\views\generic\base.py", line 69, in view
    return self.dispatch(request, *args, **kwargs)
  File "D:\Virtualenvs\wchat_shop\lib\site-packages\rest_framework\views.py", line 505, in dispatch
    response = self.handle_exception(exc)
  File "D:\Virtualenvs\wchat_shop\lib\site-packages\rest_framework\views.py", line 459, in handle_exception
    exception_handler = self.get_exception_handler()
  File "D:\Virtualenvs\wchat_shop\lib\site-packages\rest_framework\views.py", line 298, in get_exception_handler
    return self.settings.EXCEPTION_HANDLER
  File "D:\Virtualenvs\wchat_shop\lib\site-packages\rest_framework\settings.py", line 220, in __getattr__
    val = perform_import(val, attr)
  File "D:\Virtualenvs\wchat_shop\lib\site-packages\rest_framework\settings.py", line 166, in perform_import
    return import_from_string(val, setting_name)
  File "D:\Virtualenvs\wchat_shop\lib\site-packages\rest_framework\settings.py", line 180, in import_from_string
    raise ImportError(msg)
ImportError: Could not import 'utils.exception.exception_handler' for API setting 'EXCEPTION_HANDLER'. ModuleNotFoundError: No module named 'utils'.
ERROR 2020-01-06 19:45:51,956 basehttp 124 "POST /v1/food/show_detail HTTP/1.1" 500 134962
ERROR 2020-01-06 19:47:30,690 exception 118 Internal Server Error: /v1/food/show_detail
Traceback (most recent call last):
  File "D:\Virtualenvs\wchat_shop\lib\site-packages\rest_framework\views.py", line 502, in dispatch
    response = handler(request, *args, **kwargs)
  File "C:\Users\www97\Desktop\2020-01\server\api\views\store_view.py", line 31, in post
    food_detail_obj = FoodDetail.objects.filter(id=food_obj.detail_id).frist()
AttributeError: 'QuerySet' object has no attribute 'frist'

During handling of the above exception, another exception occurred:

Traceback (most recent call last):
  File "D:\Virtualenvs\wchat_shop\lib\site-packages\rest_framework\settings.py", line 177, in import_from_string
    return import_string(val)
  File "D:\Virtualenvs\wchat_shop\lib\site-packages\django\utils\module_loading.py", line 17, in import_string
    module = import_module(module_path)
  File "D:\Virtualenvs\wchat_shop\lib\importlib\__init__.py", line 126, in import_module
    return _bootstrap._gcd_import(name[level:], package, level)
  File "<frozen importlib._bootstrap>", line 994, in _gcd_import
  File "<frozen importlib._bootstrap>", line 971, in _find_and_load
  File "<frozen importlib._bootstrap>", line 941, in _find_and_load_unlocked
  File "<frozen importlib._bootstrap>", line 219, in _call_with_frames_removed
  File "<frozen importlib._bootstrap>", line 994, in _gcd_import
  File "<frozen importlib._bootstrap>", line 971, in _find_and_load
  File "<frozen importlib._bootstrap>", line 953, in _find_and_load_unlocked
ModuleNotFoundError: No module named 'utils'

During handling of the above exception, another exception occurred:

Traceback (most recent call last):
  File "D:\Virtualenvs\wchat_shop\lib\site-packages\django\core\handlers\exception.py", line 35, in inner
    response = get_response(request)
  File "D:\Virtualenvs\wchat_shop\lib\site-packages\django\core\handlers\base.py", line 128, in _get_response
    response = self.process_exception_by_middleware(e, request)
  File "D:\Virtualenvs\wchat_shop\lib\site-packages\django\core\handlers\base.py", line 126, in _get_response
    response = wrapped_callback(request, *callback_args, **callback_kwargs)
  File "D:\Virtualenvs\wchat_shop\lib\site-packages\django\views\decorators\csrf.py", line 54, in wrapped_view
    return view_func(*args, **kwargs)
  File "D:\Virtualenvs\wchat_shop\lib\site-packages\django\views\generic\base.py", line 69, in view
    return self.dispatch(request, *args, **kwargs)
  File "D:\Virtualenvs\wchat_shop\lib\site-packages\rest_framework\views.py", line 505, in dispatch
    response = self.handle_exception(exc)
  File "D:\Virtualenvs\wchat_shop\lib\site-packages\rest_framework\views.py", line 459, in handle_exception
    exception_handler = self.get_exception_handler()
  File "D:\Virtualenvs\wchat_shop\lib\site-packages\rest_framework\views.py", line 298, in get_exception_handler
    return self.settings.EXCEPTION_HANDLER
  File "D:\Virtualenvs\wchat_shop\lib\site-packages\rest_framework\settings.py", line 220, in __getattr__
    val = perform_import(val, attr)
  File "D:\Virtualenvs\wchat_shop\lib\site-packages\rest_framework\settings.py", line 166, in perform_import
    return import_from_string(val, setting_name)
  File "D:\Virtualenvs\wchat_shop\lib\site-packages\rest_framework\settings.py", line 180, in import_from_string
    raise ImportError(msg)
ImportError: Could not import 'utils.exception.exception_handler' for API setting 'EXCEPTION_HANDLER'. ModuleNotFoundError: No module named 'utils'.
ERROR 2020-01-06 19:47:30,841 basehttp 124 "POST /v1/food/show_detail HTTP/1.1" 500 134962
INFO 2020-01-06 19:49:47,305 basehttp 124 "POST /v1/food/show_detail HTTP/1.1" 200 4
INFO 2020-01-06 19:52:50,438 basehttp 124 "POST /v1/food/show_detail HTTP/1.1" 200 140
INFO 2020-01-06 21:08:35,823 basehttp 124 "POST /v1/user/login HTTP/1.1" 200 43
INFO 2020-01-06 21:11:25,838 basehttp 124 "POST /v1/user/login HTTP/1.1" 200 43
ERROR 2020-01-08 11:22:31,703 exception 118 Internal Server Error: /v1/shop_car/edite
Traceback (most recent call last):
  File "D:\Virtualenvs\wchat_shop\lib\site-packages\rest_framework\views.py", line 502, in dispatch
    response = handler(request, *args, **kwargs)
  File "D:\Virtualenvs\wchat_shop\lib\site-packages\rest_framework\views.py", line 167, in http_method_not_allowed
    raise exceptions.MethodNotAllowed(request.method)
rest_framework.exceptions.MethodNotAllowed: Method "GET" not allowed.

During handling of the above exception, another exception occurred:

Traceback (most recent call last):
  File "D:\Virtualenvs\wchat_shop\lib\site-packages\rest_framework\settings.py", line 177, in import_from_string
    return import_string(val)
  File "D:\Virtualenvs\wchat_shop\lib\site-packages\django\utils\module_loading.py", line 17, in import_string
    module = import_module(module_path)
  File "D:\Virtualenvs\wchat_shop\lib\importlib\__init__.py", line 126, in import_module
    return _bootstrap._gcd_import(name[level:], package, level)
  File "<frozen importlib._bootstrap>", line 994, in _gcd_import
  File "<frozen importlib._bootstrap>", line 971, in _find_and_load
  File "<frozen importlib._bootstrap>", line 941, in _find_and_load_unlocked
  File "<frozen importlib._bootstrap>", line 219, in _call_with_frames_removed
  File "<frozen importlib._bootstrap>", line 994, in _gcd_import
  File "<frozen importlib._bootstrap>", line 971, in _find_and_load
  File "<frozen importlib._bootstrap>", line 953, in _find_and_load_unlocked
ModuleNotFoundError: No module named 'utils'

During handling of the above exception, another exception occurred:

Traceback (most recent call last):
  File "D:\Virtualenvs\wchat_shop\lib\site-packages\django\core\handlers\exception.py", line 35, in inner
    response = get_response(request)
  File "D:\Virtualenvs\wchat_shop\lib\site-packages\django\core\handlers\base.py", line 128, in _get_response
    response = self.process_exception_by_middleware(e, request)
  File "D:\Virtualenvs\wchat_shop\lib\site-packages\django\core\handlers\base.py", line 126, in _get_response
    response = wrapped_callback(request, *callback_args, **callback_kwargs)
  File "D:\Virtualenvs\wchat_shop\lib\site-packages\django\views\decorators\csrf.py", line 54, in wrapped_view
    return view_func(*args, **kwargs)
  File "D:\Virtualenvs\wchat_shop\lib\site-packages\django\views\generic\base.py", line 69, in view
    return self.dispatch(request, *args, **kwargs)
  File "D:\Virtualenvs\wchat_shop\lib\site-packages\rest_framework\views.py", line 505, in dispatch
    response = self.handle_exception(exc)
  File "D:\Virtualenvs\wchat_shop\lib\site-packages\rest_framework\views.py", line 459, in handle_exception
    exception_handler = self.get_exception_handler()
  File "D:\Virtualenvs\wchat_shop\lib\site-packages\rest_framework\views.py", line 298, in get_exception_handler
    return self.settings.EXCEPTION_HANDLER
  File "D:\Virtualenvs\wchat_shop\lib\site-packages\rest_framework\settings.py", line 220, in __getattr__
    val = perform_import(val, attr)
  File "D:\Virtualenvs\wchat_shop\lib\site-packages\rest_framework\settings.py", line 166, in perform_import
    return import_from_string(val, setting_name)
  File "D:\Virtualenvs\wchat_shop\lib\site-packages\rest_framework\settings.py", line 180, in import_from_string
    raise ImportError(msg)
ImportError: Could not import 'utils.exception.exception_handler' for API setting 'EXCEPTION_HANDLER'. ModuleNotFoundError: No module named 'utils'.
ERROR 2020-01-08 11:22:32,143 basehttp 124 "GET /v1/shop_car/edite HTTP/1.1" 500 134419
INFO 2020-01-08 11:23:04,292 basehttp 124 "POST /v1/shop_car/edite HTTP/1.1" 200 14
INFO 2020-01-08 11:23:58,500 basehttp 124 "POST /v1/user/login HTTP/1.1" 200 43
INFO 2020-01-08 11:25:04,623 basehttp 124 "POST /v1/shop_car/edite HTTP/1.1" 200 14
INFO 2020-01-08 11:26:47,036 basehttp 124 "POST /v1/shop_car/edite HTTP/1.1" 200 59
INFO 2020-01-08 11:27:32,288 basehttp 124 "POST /v1/shop_car/edite HTTP/1.1" 200 14
INFO 2020-01-08 11:32:41,979 basehttp 124 "POST /v1/shop_car/edite HTTP/1.1" 200 14
INFO 2020-01-08 11:33:06,530 basehttp 124 "POST /v1/shop_car/edite HTTP/1.1" 200 14
INFO 2020-01-08 11:33:34,670 basehttp 124 "POST /v1/shop_car/edite HTTP/1.1" 200 14
INFO 2020-01-08 11:34:59,164 basehttp 124 "POST /v1/user/login HTTP/1.1" 200 43
INFO 2020-01-08 11:35:40,348 basehttp 124 "POST /v1/shop_car/edite HTTP/1.1" 200 59
INFO 2020-01-08 11:36:20,597 basehttp 124 "POST /v1/shop_car/edite HTTP/1.1" 200 59
ERROR 2020-01-08 11:59:20,602 exception 118 Internal Server Error: /v1/shop_car/edite
Traceback (most recent call last):
  File "D:\Virtualenvs\wchat_shop\lib\site-packages\rest_framework\views.py", line 502, in dispatch
    response = handler(request, *args, **kwargs)
  File "D:\Virtualenvs\wchat_shop\lib\site-packages\rest_framework\views.py", line 167, in http_method_not_allowed
    raise exceptions.MethodNotAllowed(request.method)
rest_framework.exceptions.MethodNotAllowed: Method "GET" not allowed.

During handling of the above exception, another exception occurred:

Traceback (most recent call last):
  File "D:\Virtualenvs\wchat_shop\lib\site-packages\rest_framework\settings.py", line 177, in import_from_string
    return import_string(val)
  File "D:\Virtualenvs\wchat_shop\lib\site-packages\django\utils\module_loading.py", line 17, in import_string
    module = import_module(module_path)
  File "D:\Virtualenvs\wchat_shop\lib\importlib\__init__.py", line 126, in import_module
    return _bootstrap._gcd_import(name[level:], package, level)
  File "<frozen importlib._bootstrap>", line 994, in _gcd_import
  File "<frozen importlib._bootstrap>", line 971, in _find_and_load
  File "<frozen importlib._bootstrap>", line 941, in _find_and_load_unlocked
  File "<frozen importlib._bootstrap>", line 219, in _call_with_frames_removed
  File "<frozen importlib._bootstrap>", line 994, in _gcd_import
  File "<frozen importlib._bootstrap>", line 971, in _find_and_load
  File "<frozen importlib._bootstrap>", line 953, in _find_and_load_unlocked
ModuleNotFoundError: No module named 'utils'

During handling of the above exception, another exception occurred:

Traceback (most recent call last):
  File "D:\Virtualenvs\wchat_shop\lib\site-packages\django\core\handlers\exception.py", line 35, in inner
    response = get_response(request)
  File "D:\Virtualenvs\wchat_shop\lib\site-packages\django\core\handlers\base.py", line 128, in _get_response
    response = self.process_exception_by_middleware(e, request)
  File "D:\Virtualenvs\wchat_shop\lib\site-packages\django\core\handlers\base.py", line 126, in _get_response
    response = wrapped_callback(request, *callback_args, **callback_kwargs)
  File "D:\Virtualenvs\wchat_shop\lib\site-packages\django\views\decorators\csrf.py", line 54, in wrapped_view
    return view_func(*args, **kwargs)
  File "D:\Virtualenvs\wchat_shop\lib\site-packages\django\views\generic\base.py", line 69, in view
    return self.dispatch(request, *args, **kwargs)
  File "D:\Virtualenvs\wchat_shop\lib\site-packages\rest_framework\views.py", line 505, in dispatch
    response = self.handle_exception(exc)
  File "D:\Virtualenvs\wchat_shop\lib\site-packages\rest_framework\views.py", line 459, in handle_exception
    exception_handler = self.get_exception_handler()
  File "D:\Virtualenvs\wchat_shop\lib\site-packages\rest_framework\views.py", line 298, in get_exception_handler
    return self.settings.EXCEPTION_HANDLER
  File "D:\Virtualenvs\wchat_shop\lib\site-packages\rest_framework\settings.py", line 220, in __getattr__
    val = perform_import(val, attr)
  File "D:\Virtualenvs\wchat_shop\lib\site-packages\rest_framework\settings.py", line 166, in perform_import
    return import_from_string(val, setting_name)
  File "D:\Virtualenvs\wchat_shop\lib\site-packages\rest_framework\settings.py", line 180, in import_from_string
    raise ImportError(msg)
ImportError: Could not import 'utils.exception.exception_handler' for API setting 'EXCEPTION_HANDLER'. ModuleNotFoundError: No module named 'utils'.
ERROR 2020-01-08 11:59:20,984 basehttp 124 "GET /v1/shop_car/edite HTTP/1.1" 500 134501
WARNING 2020-01-08 12:00:10,941 basehttp 124 "GET /v1/shop_car/edite HTTP/1.1" 405 40
WARNING 2020-01-08 12:00:47,877 basehttp 124 "GET /v1/shop_car/edite HTTP/1.1" 405 40
WARNING 2020-01-08 12:05:25,970 basehttp 124 "GET /v1/shop_car/edite HTTP/1.1" 405 40
